Workbook

Sheet Historic Stats
A1: Team | B1: Wins | C1: Loses | D1: Win % | E1: Points For | F1: Points Against | G1: Point Diff | H1: Point Diff/Gm | I1: Luck_v1 (PointDiff vs Win%) | J1: Bengal's Syndrome (Title% vs Win%) | K1: Regular Season Titles | L1: Playoff Titles | M1: Total Titles | N1: Title Rate | O1: Playoff Appearances | P1: Winnings | Q1: # of Trades
A2: Kevin | B2: =6 -> 6 | C2: =11 -> 11 | D2: =B2/(B2+C2) -> 0.35294118 | E2: =1420.98 -> 1420.98 | F2: =1767.94 -> 1767.94 | G2: =E2-F2 -> -346.96 | H2: =G2/(B2+C2) -> -20.409412 | I2: =rank(D2,$D$2:$D$14,0)-rank(H2,$H$2:$H$14,0) -> 0 | J2: =rank(M2,$M$2:$M$14,0)-rank(D2,$D$2:$D$14,0) -> -3 | K2: =vlookup($A2,'Historic League Rankings'!$A:$AT,36,false) -> 0 | L2: =vlookup($A2,'Historic League Rankings'!$A:$AT,39,false) -> 0 | M2: =K2+L2 -> 0 | N2: =vlookup(A2,'Historic League Rankings'!A:AI,35,false) -> 0 | O2: =vlookup($A2,'Historic League Rankings'!$A:$AT,38,false) -> 0 | P2: =vlookup($A2,'Historic League Rankings'!$A:$AT,41,false) -> -25 | Q2: =COUNTIF('League Trades'!B:B,A2)+COUNTIF('League Trades'!E:E,A2) -> 0
A3: Zach | B3: =8+8+10+10+5+5+8+6+8+8+9+14+11 -> 110 | C3: =9+9+7+7+12+12+9+11+10+10+9+4+7 -> 116 | D3: =B3/(B3+C3) -> 0.48672566 | E3: =1715.5+1696.02+1605.08+1651.86+1389.82+1869.18+2019.64+2021.68+2108.82+1877.18+2151.58+2267.34+2150.1 -> 24523.8 | F3: =1679.22+1715.64+1501.68+1667.02+1592.96+2030.6+1966.62+2242.8+2196.34+2026.02+2177.68+1983.26+2067.54 -> 24847.38 | G3: =E3-F3 -> -323.58 | H3: =G3/(B3+C3) -> -1.4317699 | I3: =rank(D3,$D$2:$D$14,0)-rank(H3,$H$2:$H$14,0) -> 0 | J3: =rank(M3,$M$2:$M$14,0)-rank(D3,$D$2:$D$14,0) -> 2 | K3: =vlookup($A3,'Historic League Rankings'!$A:$AT,36,false) -> 0 | L3: =vlookup($A3,'Historic League Rankings'!$A:$AT,39,false) -> 0 | M3: =K3+L3 -> 0 | N3: =vlookup(A3,'Historic League Rankings'!A:AI,35,false) -> 0 | O3: =vlookup($A3,'Historic League Rankings'!$A:$AT,38,false) -> 3 | P3: =vlookup($A3,'Historic League Rankings'!$A:$AT,41,false) -> -75 | Q3: =COUNTIF('League Trades'!B:B,A3)+COUNTIF('League Trades'!E:E,A3) -> 4
A4: Winston | B4: =8+11+7+9+8+3 -> 46 | C4: =9+6+10+8+9+14 -> 56 | D4: =B4/(B4+C4) -> 0.45098039 | E4: =1582.7+1676.8+1585.56+1498.22+1474.74+1662.46 -> 9480.48 | F4: =1654.24+1576.24+1648.36+1511.58+1499.7+2110.5 -> 10000.62 | G4: =E4-F4 -> -520.14 | H4: =G4/(B4+C4) -> -5.0994118 | I4: =rank(D4,$D$2:$D$14,0)-rank(H4,$H$2:$H$14,0) -> 0 | J4: =rank(M4,$M$2:$M$14,0)-rank(D4,$D$2:$D$14,0) -> 0 | K4: =vlookup($A4,'Historic League Rankings'!$A:$AT,36,false) -> 0 | L4: =vlookup($A4,'Historic League Rankings'!$A:$AT,39,false) -> 0 | M4: =K4+L4 -> 0 | N4: =vlookup(A4,'Historic League Rankings'!A:AI,35,false) -> 0 | O4: =vlookup($A4,'Historic League Rankings'!$A:$AT,38,false) -> 1 | P4: =vlookup($A4,'Historic League Rankings'!$A:$AT,41,false) -> -125 | Q4: =COUNTIF('League Trades'!B:B,A4)+COUNTIF('League Trades'!E:E,A4) -> 0
A5: Matt | B5: =6+3+8+11+5+8+13+10+9+9+11+11+8 -> 112 | C5: =11+14+9+6+12+9+4+7+9+9+7+7+10 -> 114 | D5: =B5/(B5+C5) -> 0.49557522 | E5: =1495.74+1332.74+1632.1+1540.12+1354.94+2204.76+2261.32+2237.74+2265.66+2159.26+2268.18+2156.62+2120.68 -> 25029.86 | F5: =1603.56+1656.6+1617.38+1467.08+1606.92+2118.86+2051.32+2042.44+2152.34+2118.98+2083.2+2034.52+2088.7 -> 24641.9 | G5: =E5-F5 -> 387.96 | H5: =G5/(B5+C5) -> 1.7166372 | I5: =rank(D5,$D$2:$D$14,0)-rank(H5,$H$2:$H$14,0) -> 3 | J5: =rank(M5,$M$2:$M$14,0)-rank(D5,$D$2:$D$14,0) -> -4 | K5: =vlookup($A5,'Historic League Rankings'!$A:$AT,36,false) -> 0 | L5: =vlookup($A5,'Historic League Rankings'!$A:$AT,39,false) -> 3 | M5: =K5+L5 -> 3 | N5: =vlookup(A5,'Historic League Rankings'!A:AI,35,false) -> 0.23076923 | O5: =vlookup($A5,'Historic League Rankings'!$A:$AT,38,false) -> 5 | P5: =vlookup($A5,'Historic League Rankings'!$A:$AT,41,false) -> -75 | Q5: =COUNTIF('League Trades'!B:B,A5)+COUNTIF('League Trades'!E:E,A5) -> 11
A6: Max | B6: =5+10+8+11+8+3+7 -> 52 | C6: =12+7+10+7+10+15+11 -> 72 | D6: =B6/(B6+C6) -> 0.41935484 | E6: =1748.62+2056.64+2326.7+2233.46+2045.48+1536.14+2121.36 -> 14068.4 | F6: =2084.02+1975.98+2364.66+2063.58+2160.22+2080+2258.08 -> 14986.54 | G6: =E6-F6 -> -918.14 | H6: =G6/(B6+C6) -> -7.4043548 | I6: =rank(D6,$D$2:$D$14,0)-rank(H6,$H$2:$H$14,0) -> 0 | J6: =rank(M6,$M$2:$M$14,0)-rank(D6,$D$2:$D$14,0) -> -2 | K6: =vlookup($A6,'Historic League Rankings'!$A:$AT,36,false) -> 0 | L6: =vlookup($A6,'Historic League Rankings'!$A:$AT,39,false) -> 0 | M6: =K6+L6 -> 0 | N6: =vlookup(A6,'Historic League Rankings'!A:AI,35,false) -> 0 | O6: =vlookup($A6,'Historic League Rankings'!$A:$AT,38,false) -> 1 | P6: =vlookup($A6,'Historic League Rankings'!$A:$AT,41,false) -> -450 | Q6: =COUNTIF('League Trades'!B:B,A6)+COUNTIF('League Trades'!E:E,A6) -> 6
A7: Ryan | B7: =4+12+13+13+4+3+10+9+8+4+6 -> 86 | C7: =13+5+4+4+13+14+8+9+10+14+12 -> 106 | D7: =B7/(B7+C7) -> 0.44791667 | E7: =1391.2+1852.16+1839.28+2483.1+1797.06+1721.58+2163.8+1993.58+1989.86+1788.62+1872.98 -> 20893.22 | F7: =1753.52+1548.34+1484.46+1937.4+2232.24+2104.34+2015.46+2062.46+1995+2201.18+2014.42 -> 21348.82 | G7: =E7-F7 -> -455.6 | H7: =G7/(B7+C7) -> -2.3729167 | I7: =rank(D7,$D$2:$D$14,0)-rank(H7,$H$2:$H$14,0) -> 2 | J7: =rank(M7,$M$2:$M$14,0)-rank(D7,$D$2:$D$14,0) -> -5 | K7: =vlookup($A7,'Historic League Rankings'!$A:$AT,36,false) -> 1 | L7: =vlookup($A7,'Historic League Rankings'!$A:$AT,39,false) -> 1 | M7: =K7+L7 -> 2 | N7: =vlookup(A7,'Historic League Rankings'!A:AI,35,false) -> 0.18181818 | O7: =vlookup($A7,'Historic League Rankings'!$A:$AT,38,false) -> 4 | P7: =vlookup($A7,'Historic League Rankings'!$A:$AT,41,false) -> -175 | Q7: =COUNTIF('League Trades'!B:B,A7)+COUNTIF('League Trades'!E:E,A7) -> 14
A8: Jordan | B8: =9+12+10+3+6+13+14+7+8+4+10+15+10 -> 121 | C8: =8+5+7+14+11+4+3+10+10+14+8+3+8 -> 105 | D8: =B8/(B8+C8) -> 0.53539823 | E8: =1736.12+1921.8+1728.02+1137.98+1490.78+2263.24+2244.32+1888.36+2224.8+1830.88+2333.44+2673.46+2225.1 -> 25698.3 | F8: =1542.84+1712.02+1587.28+1586.4+1561.4+1848.66+1971.24+2039.58+2247.3+2062.52+2149.82+2000.68+1991.14 -> 24300.88 | G8: =E8-F8 -> 1397.42 | H8: =G8/(B8+C8) -> 6.1832743 | I8: =rank(D8,$D$2:$D$14,0)-rank(H8,$H$2:$H$14,0) -> 1 | J8: =rank(M8,$M$2:$M$14,0)-rank(D8,$D$2:$D$14,0) -> -2 | K8: =vlookup($A8,'Historic League Rankings'!$A:$AT,36,false) -> 3 | L8: =vlookup($A8,'Historic League Rankings'!$A:$AT,39,false) -> 2 | M8: =K8+L8 -> 5 | N8: =vlookup(A8,'Historic League Rankings'!A:AI,35,false) -> 0.38461538 | O8: =vlookup($A8,'Historic League Rankings'!$A:$AT,38,false) -> 8 | P8: =vlookup($A8,'Historic League Rankings'!$A:$AT,41,false) -> 375 | Q8: =COUNTIF('League Trades'!B:B,A8)+COUNTIF('League Trades'!E:E,A8) -> 31
A9: Ben | B9: =6+11+9+7+10+5+10+9+7+12+8+8+5 -> 107 | C9: =11+6+8+10+7+12+7+8+11+6+10+10+13 -> 119 | D9: =B9/(B9+C9) -> 0.47345133 | E9: =1550.16+1642.88+1487.92+1613.06+1514.34+1712.32+2023.14+1953.56+1850.62+2193.36+2119.3+2141.2+1791.52 -> 23593.38 | F9: =1674.64+1467.58+1615.46+1624.98+1567.96+2161.36+1953.04+1990.38+2169.22+2053.14+2163.76+2186.88+2180.82 -> 24809.22 | G9: =E9-F9 -> -1215.84 | H9: =G9/(B9+C9) -> -5.379823 | I9: =rank(D9,$D$2:$D$14,0)-rank(H9,$H$2:$H$14,0) -> -2 | J9: =rank(M9,$M$2:$M$14,0)-rank(D9,$D$2:$D$14,0) -> -6 | K9: =vlookup($A9,'Historic League Rankings'!$A:$AT,36,false) -> 1 | L9: =vlookup($A9,'Historic League Rankings'!$A:$AT,39,false) -> 2 | M9: =K9+L9 -> 3 | N9: =vlookup(A9,'Historic League Rankings'!A:AI,35,false) -> 0.23076923 | O9: =vlookup($A9,'Historic League Rankings'!$A:$AT,38,false) -> 4 | P9: =vlookup($A9,'Historic League Rankings'!$A:$AT,41,false) -> -275 | Q9: =COUNTIF('League Trades'!B:B,A9)+COUNTIF('League Trades'!E:E,A9) -> 22
A10: Mike | B10: =9+8+11+8+7+5+5+11+12+12+11+7+9 -> 115 | C10: =8+9+6+9+10+12+12+6+6+6+7+11+9 -> 111 | D10: =B10/(B10+C10) -> 0.50884956 | E10: =1700.24+1552.9+1694.18+1644.58+1531.4+1888.58+2032.36+2213.72+2352.8+2174.16+2214.62+ 1910.78+1851.14 -> 24761.46 | F10: =1711.16+1592.82+1546.72+1613.28+1550.9+2189.72+2066.38+2030.74+2104.78+1979.06+2136.22+2173.26+1982.78 -> 24677.82 | G10: =E10-F10 -> 83.64 | H10: =G10/(B10+C10) -> 0.3700885 | I10: =rank(D10,$D$2:$D$14,0)-rank(H10,$H$2:$H$14,0) -> -2 | J10: =rank(M10,$M$2:$M$14,0)-rank(D10,$D$2:$D$14,0) -> 1 | K10: =vlookup($A10,'Historic League Rankings'!$A:$AT,36,false) -> 2 | L10: =vlookup($A10,'Historic League Rankings'!$A:$AT,39,false) -> 0 | M10: =K10+L10 -> 2 | N10: =vlookup(A10,'Historic League Rankings'!A:AI,35,false) -> 0.15384615 | O10: =vlookup($A10,'Historic League Rankings'!$A:$AT,38,false) -> 5 | P10: =vlookup($A10,'Historic League Rankings'!$A:$AT,41,false) -> 100 | Q10: =COUNTIF('League Trades'!B:B,A10)+COUNTIF('League Trades'!E:E,A10) -> 4
A11: Russell | B11: =10+12+10+11+8+10+9+7+10+3+14+12+12 -> 128 | C11: =7+5+7+6+9+7+8+10+8+15+4+6+6 -> 98 | D11: =B11/(B11+C11) -> 0.56637168 | E11: =1815.08+1807.68+1718.96+1748.12+1398.46+2149.22+2029.9+2099.28+2099.92+1894.84+2332.78+2332.78+2218.24 -> 25645.26 | F11: =1720.28+1548.9+1610.22+1567.7+1302.06+2049.9+2025.94+2124.6+2137.86+2208.68+2014.32+2055.12+1970.02 -> 24335.6 | G11: =E11-F11 -> 1309.66 | H11: =G11/(B11+C11) -> 5.7949558 | I11: =rank(D11,$D$2:$D$14,0)-rank(H11,$H$2:$H$14,0) -> -1 | J11: =rank(M11,$M$2:$M$14,0)-rank(D11,$D$2:$D$14,0) -> 4 | K11: =vlookup($A11,'Historic League Rankings'!$A:$AT,36,false) -> 1 | L11: =vlookup($A11,'Historic League Rankings'!$A:$AT,39,false) -> 1 | M11: =K11+L11 -> 2 | N11: =vlookup(A11,'Historic League Rankings'!A:AI,35,false) -> 0.15384615 | O11: =vlookup($A11,'Historic League Rankings'!$A:$AT,38,false) -> 9 | P11: =vlookup($A11,'Historic League Rankings'!$A:$AT,41,false) -> 225 | Q11: =COUNTIF('League Trades'!B:B,A11)+COUNTIF('League Trades'!E:E,A11) -> 3
A12: Qasim | B12: =6+6+11+8+14+9+7+11+9+10+7+12+9 -> 119 | C12: =11+11+6+9+3+8+10+6+9+8+11+6+9 -> 107 | D12: =B12/(B12+C12) -> 0.52654867 | E12: =1520.5+1581.16+1615.44+1505.98+1586.56+2018.62+2052.86+2254.28+2182.14+1963.4+2036.36+2335.7+2056.22 -> 24709.22 | F12: =1732.06+1747.1+1495.68+1542.5+1409.66+2094.04+1976.56+2017.02+2236.16+1891.42+2106.92+2076.2+2151.82 -> 24477.14 | G12: =E12-F12 -> 232.08 | H12: =G12/(B12+C12) -> 1.0269027 | I12: =rank(D12,$D$2:$D$14,0)-rank(H12,$H$2:$H$14,0) -> -1 | J12: =rank(M12,$M$2:$M$14,0)-rank(D12,$D$2:$D$14,0) -> -1 | K12: =vlookup($A12,'Historic League Rankings'!$A:$AT,36,false) -> 2 | L12: =vlookup($A12,'Historic League Rankings'!$A:$AT,39,false) -> 1 | M12: =K12+L12 -> 3 | N12: =vlookup(A12,'Historic League Rankings'!A:AI,35,false) -> 0.23076923 | O12: =vlookup($A12,'Historic League Rankings'!$A:$AT,38,false) -> 4 | P12: =vlookup($A12,'Historic League Rankings'!$A:$AT,41,false) -> 100 | Q12: =COUNTIF('League Trades'!B:B,A12)+COUNTIF('League Trades'!E:E,A12) -> 11
A13: Johnny | B13: =9+8+5+6+9+14+10+11+9+12+4+4+13 -> 114 | C13: =8+9+12+11+8+3+7+6+9+6+14+14+5 -> 112 | D13: =B13/(B13+C13) -> 0.50442478 | E13: =1716.7+1762.28+1526.62+1589.68+1412.98+2321.8+2171.04+2149.86+2225.82+2164.94+1961.58+1826.2+2301.22 -> 25130.72 | F13: =1733.26+1610.4+1608.78+1652.88+1417.28+2032.24+2052.9+2028.82+2176.96+2019.2+2466.04+2177.74+2003.24 -> 24979.74 | G13: =E13-F13 -> 150.98 | H13: =G13/(B13+C13) -> 0.6680531 | I13: =rank(D13,$D$2:$D$14,0)-rank(H13,$H$2:$H$14,0) -> 0 | J13: =rank(M13,$M$2:$M$14,0)-rank(D13,$D$2:$D$14,0) -> -5 | K13: =vlookup($A13,'Historic League Rankings'!$A:$AT,36,false) -> 2 | L13: =vlookup($A13,'Historic League Rankings'!$A:$AT,39,false) -> 3 | M13: =K13+L13 -> 5 | N13: =vlookup(A13,'Historic League Rankings'!A:AI,35,false) -> 0.38461538 | O13: =vlookup($A13,'Historic League Rankings'!$A:$AT,38,false) -> 7 | P13: =vlookup($A13,'Historic League Rankings'!$A:$AT,41,false) -> 300 | Q13: =COUNTIF('League Trades'!B:B,A13)+COUNTIF('League Trades'!E:E,A13) -> 3
A14: Eric | B14: =14 -> 14 | C14: =3 -> 3 | D14: =B14/(B14+C14) -> 0.82352941 | E14: =1882.02 -> 1882.02 | F14: =1663.5 -> 1663.5 | G14: =E14-F14 -> 218.52 | H14: =G14/(B14+C14) -> 12.854118 | I14: =rank(D14,$D$2:$D$14,0)-rank(H14,$H$2:$H$14,0) -> 0 | J14: =rank(M14,$M$2:$M$14,0)-rank(D14,$D$2:$D$14,0) -> 8 | K14: =vlookup($A14,'Historic League Rankings'!$A:$AT,36,false) -> 1 | L14: =vlookup($A14,'Historic League Rankings'!$A:$AT,39,false) -> 0 | M14: =K14+L14 -> 1 | N14: =vlookup(A14,'Historic League Rankings'!A:AI,35,false) -> 1 | O14: =vlookup($A14,'Historic League Rankings'!$A:$AT,38,false) -> 1 | P14: =vlookup($A14,'Historic League Rankings'!$A:$AT,41,false) -> 100 | Q14: =COUNTIF('League Trades'!B:B,A14)+COUNTIF('League Trades'!E:E,A14) -> 0
B16: =SUM(B2:B14)=SUM(C2:C14) -> TRUE | E16: =SUM(E2:E14)=SUM(F2:F14) -> TRUE

Sheet Historic League Rankings
A1: Team | B1: 2013 - R | C1: 2013 - P | D1: 2014 - R | E1: 2014 - P | F1: 2015 - R | G1: 2015 - P | H1: 2016 - R | I1: 2016 - P | J1: 2017 - R | K1: 2017 - P | L1: 2018 - R | M1: 2018 - P | N1: 2019 - R | O1: 2019 - P | P1: 2020 - R | Q1: 2020 - P | R1: 2021-R | S1: 2021-P | T1: 2022-R | U1: 2022-P | V1: 2023-R | W1: 2023-P | X1: 2024-R | Y1: 2024-P | Z1: 2025-R | AA1: 2025-P | AB1: Total Score | AC1: Total Score/Season | AD1: R Score | AE1: R Score/Season | AF1: P Score | AG1: P Score/Season | AH1: Total Titles | AI1: Title Rate | AJ1: R Titles | AK1: R Title Rate | AL1: Make Playoffs | AM1: P Titles | AN1: P Title Rate | AO1: Profit | AP1: Profit/Season | AQ1: Rank Sum | AR1: Rank Sum/Season | AS1: League Ranking | AT1: League Rank/Season | AU1: ="Seasons - " & COUNT(B2:AA2)/2 -> Seasons - 13
A2: Jordan | B2: 8 | C2: 3 | D2: 10 | E2: 3 | F2: 8 | G2: 5 | H2: 1 | I2: 0 | J2: 3 | K2: 0 | L2: 8 | M2: 3 | N2: 10 | O2: 4 | P2: 3 | Q2: 0 | R2: 3 | S2: 0 | T2: 2 | U2: 0 | V2: 7 | W2: 5 | X2: 10 | Y2: 3 | Z2: 7 | AA2: 3 | AB2: =AD2+AF2 -> 109 | AC2: =AE2+AG2 -> 8.3846154 | AD2: =SUM(B2,D2,F2,H2,J2,L2,N2,P2,R2,T2,V2,X2,Z2) -> 80 | AE2: =AD2/(COUNT($B2:$AA2)/2) -> 6.1538462 | AF2: =SUM(C2,E2,G2,I2,K2,M2,O2,Q2,S2,U2,W2,Y2,AA2) -> 29 | AG2: =AF2/(COUNT($B2:$AA2)/2) -> 2.2307692 | AH2: =AJ2+AM2 -> 5 | AI2: =AK2+AN2 -> 0.38461538 | AJ2: =COUNTIF(B2:AA2,10) -> 3 | AK2: =AJ2/(COUNT($B2:$AA2)/2) -> 0.23076923 | AL2: =COUNTIFS(B2:AA2,">6") -> 8 | AM2: =COUNTIFS(B2:AA2,"=5",$B$1:$AA$1,"*P*") -> 2 | AN2: =AM2/(COUNT($B2:$AA2)/2) -> 0.15384615 | AO2: =(((COUNT(B2:M2)/2)*-25)+((Count(N2:W2)/2)*-50)+((Count(X2:AA2)/2)*-100))+((COUNTIF(B2:M2,10))*100)+((COUNTIF(B2:M2,9))*50)+((COUNTIF(B2:M2,8))*25)+((COUNTIF(N2:W2,10))*200)+((COUNTIF(N2:W2,9))*100)+((COUNTIF(N2:W2,8))*50)+((COUNTIF(X2:AA2,10))*400)+((COUNTIF(X2:AA2,9))*200)+((COUNTIF(X2:AA2,8))*100)+((COUNTIFS(B2:M2,5,$B$1:$M$1,"*P*")*50))+((COUNTIFS(B2:M2,4,$B$1:$M$1,"*P*")*25))+((COUNTIFS(N2:W2,5,$N$1:$W$1,"*P*")*100))+((COUNTIFS(N2:W2,4,$N$1:$W$1,"*P*")*50))+((COUNTIFS(X2:AA2,5,$X$1:$AA$1,"*P*")*200))+((COUNTIFS(X2:AA2,4,$X$1:$AA$1,"*P*")*100)) -> 375 | AP2: =AO2/(COUNT($B2:$AA2)/2) -> 28.846154 | AQ2: =('Weights of Rankings'!$D$1*rank(AB2,$AB$2:$AB$14,0))+('Weights of Rankings'!$D$3*rank(AD2,$AD$2:$AD$14,0))+('Weights of Rankings'!$D$5*rank(AF2,$AF$2:$AF$14,0))+('Weights of Rankings'!$D$7*rank(AH2,$AH$2:$AH$14,0))+('Weights of Rankings'!$D$8*rank(AJ2,$AJ$2:$AJ$14,0))+('Weights of Rankings'!$D$9*rank(AL2,$AL$2:$AL$14,0))+('Weights of Rankings'!$D$11*rank(AM2,$AM$2:$AM$14,0))+('Weights of Rankings'!$D$12*rank(AO2,$AO$2:$AO$14,0)) -> 13 | AR2: =('Weights of Rankings'!$D$1*rank(AC2,$AC$2:$AC$14,0))+('Weights of Rankings'!$D$3*rank(AE2,$AE$2:$AE$14,0))+('Weights of Rankings'!$D$5*rank(AG2,$AG$2:$AG$14,0))+('Weights of Rankings'!$D$7*rank(AI2,$AI$2:$AI$14,0))+('Weights of Rankings'!$D$8*rank(AK2,$AK$2:$AK$14,0))+('Weights of Rankings'!$D$9*rank(AM2,$AM$2:$AM$14,0))+('Weights of Rankings'!$D$11*rank(AN2,$AN$2:$AN$14,0))+('Weights of Rankings'!$D$12*rank(AP2,$AP$2:$AP$14,0)) -> 21 | AS2: =rank(AQ2,$AQ$2:$AQ$14,1) -> 1 | AT2: =rank(AR2,$AR$2:$AR$14,1) -> 1
A3: Mike | B3: 6 | C3: 0 | D3: 4 | E3: 0 | F3: 10 | G3: 3 | H3: 5 | I3: 0 | J3: 4 | K3: 0 | L3: 4 | M3: 0 | N3: 3 | O3: 0 | P3: 9 | Q3: 3 | R3: 10 | S3: 4 | T3: 9 | U3: 4 | V3: 8 | W3: 4 | X3: 4 | Y3: 0 | Z3: 5 | AA3: 0 | AB3: =AD3+AF3 -> 99 | AC3: =AE3+AG3 -> 7.6153846 | AD3: =SUM(B3,D3,F3,H3,J3,L3,N3,P3,R3,T3,V3,X3,Z3) -> 81 | AE3: =AD3/(COUNT($B3:$AA3)/2) -> 6.2307692 | AF3: =SUM(C3,E3,G3,I3,K3,M3,O3,Q3,S3,U3,W3,Y3,AA3) -> 18 | AG3: =AF3/(COUNT($B3:$AA3)/2) -> 1.3846154 | AH3: =AJ3+AM3 -> 2 | AI3: =AK3+AN3 -> 0.15384615 | AJ3: =COUNTIF(B3:AA3,10) -> 2 | AK3: =AJ3/(COUNT($B3:$AA3)/2) -> 0.15384615 | AL3: =COUNTIFS(B3:AA3,">6") -> 5 | AM3: =COUNTIFS(B3:AA3,"=5",$B$1:$AA$1,"*P*") -> 0 | AN3: =AM3/(COUNT($B3:$AA3)/2) -> 0 | AO3: =(((COUNT(B3:M3)/2)*-25)+((Count(N3:W3)/2)*-50)+((Count(X3:AA3)/2)*-100))+((COUNTIF(B3:M3,10))*100)+((COUNTIF(B3:M3,9))*50)+((COUNTIF(B3:M3,8))*25)+((COUNTIF(N3:W3,10))*200)+((COUNTIF(N3:W3,9))*100)+((COUNTIF(N3:W3,8))*50)+((COUNTIF(X3:AA3,10))*400)+((COUNTIF(X3:AA3,9))*200)+((COUNTIF(X3:AA3,8))*100)+((COUNTIFS(B3:M3,5,$B$1:$M$1,"*P*")*50))+((COUNTIFS(B3:M3,4,$B$1:$M$1,"*P*")*25))+((COUNTIFS(N3:W3,5,$N$1:$W$1,"*P*")*100))+((COUNTIFS(N3:W3,4,$N$1:$W$1,"*P*")*50))+((COUNTIFS(X3:AA3,5,$X$1:$AA$1,"*P*")*200))+((COUNTIFS(X3:AA3,4,$X$1:$AA$1,"*P*")*100)) -> 100 | AP3: =AO3/(COUNT($B3:$AA3)/2) -> 7.6923077 | AQ3: =('Weights of Rankings'!$D$1*rank(AB3,$AB$2:$AB$14,0))+('Weights of Rankings'!$D$3*rank(AD3,$AD$2:$AD$14,0))+('Weights of Rankings'!$D$5*rank(AF3,$AF$2:$AF$14,0))+('Weights of Rankings'!$D$7*rank(AH3,$AH$2:$AH$14,0))+('Weights of Rankings'!$D$8*rank(AJ3,$AJ$2:$AJ$14,0))+('Weights of Rankings'!$D$9*rank(AL3,$AL$2:$AL$14,0))+('Weights of Rankings'!$D$11*rank(AM3,$AM$2:$AM$14,0))+('Weights of Rankings'!$D$12*rank(AO3,$AO$2:$AO$14,0)) -> 31 | AR3: =('Weights of Rankings'!$D$1*rank(AC3,$AC$2:$AC$14,0))+('Weights of Rankings'!$D$3*rank(AE3,$AE$2:$AE$14,0))+('Weights of Rankings'!$D$5*rank(AG3,$AG$2:$AG$14,0))+('Weights of Rankings'!$D$7*rank(AI3,$AI$2:$AI$14,0))+('Weights of Rankings'!$D$8*rank(AK3,$AK$2:$AK$14,0))+('Weights of Rankings'!$D$9*rank(AM3,$AM$2:$AM$14,0))+('Weights of Rankings'!$D$11*rank(AN3,$AN$2:$AN$14,0))+('Weights of Rankings'!$D$12*rank(AP3,$AP$2:$AP$14,0)) -> 45 | AS3: =rank(AQ3,$AQ$2:$AQ$14,1) -> 4 | AT3: =rank(AR3,$AR$2:$AR$14,1) -> 7
A4: Ben | B4: 3 | C4: 0 | D4: 7 | E4: 5 | F4: 5 | G4: 0 | H4: 3 | I4: 0 | J4: 8 | K4: 5 | L4: 2 | M4: 0 | N4: 7 | O4: 3 | P4: 5 | Q4: 0 | R4: 1 | S4: 0 | T4: 10 | U4: 3 | V4: 5 | W4: 0 | X4: 5 | Y4: 0 | Z4: 1 | AA4: 0 | AB4: =AD4+AF4 -> 78 | AC4: =AE4+AG4 -> 6 | AD4: =SUM(B4,D4,F4,H4,J4,L4,N4,P4,R4,T4,V4,X4,Z4) -> 62 | AE4: =AD4/(COUNT($B4:$AA4)/2) -> 4.7692308 | AF4: =SUM(C4,E4,G4,I4,K4,M4,O4,Q4,S4,U4,W4,Y4,AA4) -> 16 | AG4: =AF4/(COUNT($B4:$AA4)/2) -> 1.2307692 | AH4: =AJ4+AM4 -> 3 | AI4: =AK4+AN4 -> 0.23076923 | AJ4: =COUNTIF(B4:AA4,10) -> 1 | AK4: =AJ4/(COUNT($B4:$AA4)/2) -> 0.076923077 | AL4: =COUNTIFS(B4:AA4,">6") -> 4 | AM4: =COUNTIFS(B4:AA4,"=5",$B$1:$AA$1,"*P*") -> 2 | AN4: =AM4/(COUNT($B4:$AA4)/2) -> 0.15384615 | AO4: =(((COUNT(B4:M4)/2)*-25)+((Count(N4:W4)/2)*-50)+((Count(X4:AA4)/2)*-100))+((COUNTIF(B4:M4,10))*100)+((COUNTIF(B4:M4,9))*50)+((COUNTIF(B4:M4,8))*25)+((COUNTIF(N4:W4,10))*200)+((COUNTIF(N4:W4,9))*100)+((COUNTIF(N4:W4,8))*50)+((COUNTIF(X4:AA4,10))*400)+((COUNTIF(X4:AA4,9))*200)+((COUNTIF(X4:AA4,8))*100)+((COUNTIFS(B4:M4,5,$B$1:$M$1,"*P*")*50))+((COUNTIFS(B4:M4,4,$B$1:$M$1,"*P*")*25))+((COUNTIFS(N4:W4,5,$N$1:$W$1,"*P*")*100))+((COUNTIFS(N4:W4,4,$N$1:$W$1,"*P*")*50))+((COUNTIFS(X4:AA4,5,$X$1:$AA$1,"*P*")*200))+((COUNTIFS(X4:AA4,4,$X$1:$AA$1,"*P*")*100)) -> -275 | AP4: =AO4/(COUNT($B4:$AA4)/2) -> -21.153846 | AQ4: =('Weights of Rankings'!$D$1*rank(AB4,$AB$2:$AB$14,0))+('Weights of Rankings'!$D$3*rank(AD4,$AD$2:$AD$14,0))+('Weights of Rankings'!$D$5*rank(AF4,$AF$2:$AF$14,0))+('Weights of Rankings'!$D$7*rank(AH4,$AH$2:$AH$14,0))+('Weights of Rankings'!$D$8*rank(AJ4,$AJ$2:$AJ$14,0))+('Weights of Rankings'!$D$9*rank(AL4,$AL$2:$AL$14,0))+('Weights of Rankings'!$D$11*rank(AM4,$AM$2:$AM$14,0))+('Weights of Rankings'!$D$12*rank(AO4,$AO$2:$AO$14,0)) -> 74 | AR4: =('Weights of Rankings'!$D$1*rank(AC4,$AC$2:$AC$14,0))+('Weights of Rankings'!$D$3*rank(AE4,$AE$2:$AE$14,0))+('Weights of Rankings'!$D$5*rank(AG4,$AG$2:$AG$14,0))+('Weights of Rankings'!$D$7*rank(AI4,$AI$2:$AI$14,0))+('Weights of Rankings'!$D$8*rank(AK4,$AK$2:$AK$14,0))+('Weights of Rankings'!$D$9*rank(AM4,$AM$2:$AM$14,0))+('Weights of Rankings'!$D$11*rank(AN4,$AN$2:$AN$14,0))+('Weights of Rankings'!$D$12*rank(AP4,$AP$2:$AP$14,0)) -> 67 | AS4: =rank(AQ4,$AQ$2:$AQ$14,1) -> 10 | AT4: =rank(AR4,$AR$2:$AR$14,1) -> 10
A5: Russell | B5: 9 | C5: 3 | D5: 9 | E5: 4 | F5: 7 | G5: 3 | H5: 9 | I5: 3 | J5: 5 | K5: 0 | L5: 7 | M5: 3 | N5: 6 | O5: 0 | P5: 4 | Q5: 0 | R5: 8 | S5: 3 | T5: 1 | U5: 0 | V5: 10 | W5: 3 | X5: 7 | Y5: 3 | Z5: 9 | AA5: 5 | AB5: =AD5+AF5 -> 121 | AC5: =AE5+AG5 -> 9.3076923 | AD5: =SUM(B5,D5,F5,H5,J5,L5,N5,P5,R5,T5,V5,X5,Z5) -> 91 | AE5: =AD5/(COUNT($B5:$AA5)/2) -> 7 | AF5: =SUM(C5,E5,G5,I5,K5,M5,O5,Q5,S5,U5,W5,Y5,AA5) -> 30 | AG5: =AF5/(COUNT($B5:$AA5)/2) -> 2.3076923 | AH5: =AJ5+AM5 -> 2 | AI5: =AK5+AN5 -> 0.15384615 | AJ5: =COUNTIF(B5:AA5,10) -> 1 | AK5: =AJ5/(COUNT($B5:$AA5)/2) -> 0.076923077 | AL5: =COUNTIFS(B5:AA5,">6") -> 9 | AM5: =COUNTIFS(B5:AA5,"=5",$B$1:$AA$1,"*P*") -> 1 | AN5: =AM5/(COUNT($B5:$AA5)/2) -> 0.076923077 | AO5: =(((COUNT(B5:M5)/2)*-25)+((Count(N5:W5)/2)*-50)+((Count(X5:AA5)/2)*-100))+((COUNTIF(B5:M5,10))*100)+((COUNTIF(B5:M5,9))*50)+((COUNTIF(B5:M5,8))*25)+((COUNTIF(N5:W5,10))*200)+((COUNTIF(N5:W5,9))*100)+((COUNTIF(N5:W5,8))*50)+((COUNTIF(X5:AA5,10))*400)+((COUNTIF(X5:AA5,9))*200)+((COUNTIF(X5:AA5,8))*100)+((COUNTIFS(B5:M5,5,$B$1:$M$1,"*P*")*50))+((COUNTIFS(B5:M5,4,$B$1:$M$1,"*P*")*25))+((COUNTIFS(N5:W5,5,$N$1:$W$1,"*P*")*100))+((COUNTIFS(N5:W5,4,$N$1:$W$1,"*P*")*50))+((COUNTIFS(X5:AA5,5,$X$1:$AA$1,"*P*")*200))+((COUNTIFS(X5:AA5,4,$X$1:$AA$1,"*P*")*100)) -> 225 | AP5: =AO5/(COUNT($B5:$AA5)/2) -> 17.307692 | AQ5: =('Weights of Rankings'!$D$1*rank(AB5,$AB$2:$AB$14,0))+('Weights of Rankings'!$D$3*rank(AD5,$AD$2:$AD$14,0))+('Weights of Rankings'!$D$5*rank(AF5,$AF$2:$AF$14,0))+('Weights of Rankings'!$D$7*rank(AH5,$AH$2:$AH$14,0))+('Weights of Rankings'!$D$8*rank(AJ5,$AJ$2:$AJ$14,0))+('Weights of Rankings'!$D$9*rank(AL5,$AL$2:$AL$14,0))+('Weights of Rankings'!$D$11*rank(AM5,$AM$2:$AM$14,0))+('Weights of Rankings'!$D$12*rank(AO5,$AO$2:$AO$14,0)) -> 16 | AR5: =('Weights of Rankings'!$D$1*rank(AC5,$AC$2:$AC$14,0))+('Weights of Rankings'!$D$3*rank(AE5,$AE$2:$AE$14,0))+('Weights of Rankings'!$D$5*rank(AG5,$AG$2:$AG$14,0))+('Weights of Rankings'!$D$7*rank(AI5,$AI$2:$AI$14,0))+('Weights of Rankings'!$D$8*rank(AK5,$AK$2:$AK$14,0))+('Weights of Rankings'!$D$9*rank(AM5,$AM$2:$AM$14,0))+('Weights of Rankings'!$D$11*rank(AN5,$AN$2:$AN$14,0))+('Weights of Rankings'!$D$12*rank(AP5,$AP$2:$AP$14,0)) -> 30 | AS5: =rank(AQ5,$AQ$2:$AQ$14,1) -> 2 | AT5: =rank(AR5,$AR$2:$AR$14,1) -> 4
A6: Matt | B6: 1 | C6: 0 | D6: 1 | E6: 0 | F6: 4 | G6: 0 | H6: 8 | I6: 3 | J6: 1 | K6: 0 | L6: 5 | M6: 0 | N6: 9 | O6: 5 | P6: 7 | Q6: 5 | R6: 7 | S6: 5 | T6: 5 | U6: 0 | V6: 9 | W6: 3 | X6: 6 | Y6: 0 | Z6: 4 | AA6: 0 | AB6: =AD6+AF6 -> 88 | AC6: =AE6+AG6 -> 6.7692308 | AD6: =SUM(B6,D6,F6,H6,J6,L6,N6,P6,R6,T6,V6,X6,Z6) -> 67 | AE6: =AD6/(COUNT($B6:$AA6)/2) -> 5.1538462 | AF6: =SUM(C6,E6,G6,I6,K6,M6,O6,Q6,S6,U6,W6,Y6,AA6) -> 21 | AG6: =AF6/(COUNT($B6:$AA6)/2) -> 1.6153846 | AH6: =AJ6+AM6 -> 3 | AI6: =AK6+AN6 -> 0.23076923 | AJ6: =COUNTIF(B6:AA6,10) -> 0 | AK6: =AJ6/(COUNT($B6:$AA6)/2) -> 0 | AL6: =COUNTIFS(B6:AA6,">6") -> 5 | AM6: =COUNTIFS(B6:AA6,"=5",$B$1:$AA$1,"*P*") -> 3 | AN6: =AM6/(COUNT($B6:$AA6)/2) -> 0.23076923 | AO6: =(((COUNT(B6:M6)/2)*-25)+((Count(N6:W6)/2)*-50)+((Count(X6:AA6)/2)*-100))+((COUNTIF(B6:M6,10))*100)+((COUNTIF(B6:M6,9))*50)+((COUNTIF(B6:M6,8))*25)+((COUNTIF(N6:W6,10))*200)+((COUNTIF(N6:W6,9))*100)+((COUNTIF(N6:W6,8))*50)+((COUNTIF(X6:AA6,10))*400)+((COUNTIF(X6:AA6,9))*200)+((COUNTIF(X6:AA6,8))*100)+((COUNTIFS(B6:M6,5,$B$1:$M$1,"*P*")*50))+((COUNTIFS(B6:M6,4,$B$1:$M$1,"*P*")*25))+((COUNTIFS(N6:W6,5,$N$1:$W$1,"*P*")*100))+((COUNTIFS(N6:W6,4,$N$1:$W$1,"*P*")*50))+((COUNTIFS(X6:AA6,5,$X$1:$AA$1,"*P*")*200))+((COUNTIFS(X6:AA6,4,$X$1:$AA$1,"*P*")*100)) -> -75 | AP6: =AO6/(COUNT($B6:$AA6)/2) -> -5.7692308 | AQ6: =('Weights of Rankings'!$D$1*rank(AB6,$AB$2:$AB$14,0))+('Weights of Rankings'!$D$3*rank(AD6,$AD$2:$AD$14,0))+('Weights of Rankings'!$D$5*rank(AF6,$AF$2:$AF$14,0))+('Weights of Rankings'!$D$7*rank(AH6,$AH$2:$AH$14,0))+('Weights of Rankings'!$D$8*rank(AJ6,$AJ$2:$AJ$14,0))+('Weights of Rankings'!$D$9*rank(AL6,$AL$2:$AL$14,0))+('Weights of Rankings'!$D$11*rank(AM6,$AM$2:$AM$14,0))+('Weights of Rankings'!$D$12*rank(AO6,$AO$2:$AO$14,0)) -> 50 | AR6: =('Weights of Rankings'!$D$1*rank(AC6,$AC$2:$AC$14,0))+('Weights of Rankings'!$D$3*rank(AE6,$AE$2:$AE$14,0))+('Weights of Rankings'!$D$5*rank(AG6,$AG$2:$AG$14,0))+('Weights of Rankings'!$D$7*rank(AI6,$AI$2:$AI$14,0))+('Weights of Rankings'!$D$8*rank(AK6,$AK$2:$AK$14,0))+('Weights of Rankings'!$D$9*rank(AM6,$AM$2:$AM$14,0))+('Weights of Rankings'!$D$11*rank(AN6,$AN$2:$AN$14,0))+('Weights of Rankings'!$D$12*rank(AP6,$AP$2:$AP$14,0)) -> 42 | AS6: =rank(AQ6,$AQ$2:$AQ$14,1) -> 6 | AT6: =rank(AR6,$AR$2:$AR$14,1) -> 5
A7: Qasim | B7: 2 | C7: 0 | D7: 3 | E7: 0 | F7: 9 | G7: 4 | H7: 4 | I7: 0 | J7: 10 | K7: 4 | L7: 6 | M7: 0 | N7: 4 | O7: 0 | P7: 10 | Q7: 3 | R7: 5 | S7: 0 | T7: 6 | U7: 0 | V7: 2 | W7: 0 | X7: 8 | Y7: 5 | Z7: 6 | AA7: 0 | AB7: =AD7+AF7 -> 91 | AC7: =AE7+AG7 -> 7 | AD7: =SUM(B7,D7,F7,H7,J7,L7,N7,P7,R7,T7,V7,X7,Z7) -> 75 | AE7: =AD7/(COUNT($B7:$AA7)/2) -> 5.7692308 | AF7: =SUM(C7,E7,G7,I7,K7,M7,O7,Q7,S7,U7,W7,Y7,AA7) -> 16 | AG7: =AF7/(COUNT($B7:$AA7)/2) -> 1.2307692 | AH7: =AJ7+AM7 -> 3 | AI7: =AK7+AN7 -> 0.23076923 | AJ7: =COUNTIF(B7:AA7,10) -> 2 | AK7: =AJ7/(COUNT($B7:$AA7)/2) -> 0.15384615 | AL7: =COUNTIFS(B7:AA7,">6") -> 4 | AM7: =COUNTIFS(B7:AA7,"=5",$B$1:$AA$1,"*P*") -> 1 | AN7: =AM7/(COUNT($B7:$AA7)/2) -> 0.076923077 | AO7: =(((COUNT(B7:M7)/2)*-25)+((Count(N7:W7)/2)*-50)+((Count(X7:AA7)/2)*-100))+((COUNTIF(B7:M7,10))*100)+((COUNTIF(B7:M7,9))*50)+((COUNTIF(B7:M7,8))*25)+((COUNTIF(N7:W7,10))*200)+((COUNTIF(N7:W7,9))*100)+((COUNTIF(N7:W7,8))*50)+((COUNTIF(X7:AA7,10))*400)+((COUNTIF(X7:AA7,9))*200)+((COUNTIF(X7:AA7,8))*100)+((COUNTIFS(B7:M7,5,$B$1:$M$1,"*P*")*50))+((COUNTIFS(B7:M7,4,$B$1:$M$1,"*P*")*25))+((COUNTIFS(N7:W7,5,$N$1:$W$1,"*P*")*100))+((COUNTIFS(N7:W7,4,$N$1:$W$1,"*P*")*50))+((COUNTIFS(X7:AA7,5,$X$1:$AA$1,"*P*")*200))+((COUNTIFS(X7:AA7,4,$X$1:$AA$1,"*P*")*100)) -> 100 | AP7: =AO7/(COUNT($B7:$AA7)/2) -> 7.6923077 | AQ7: =('Weights of Rankings'!$D$1*rank(AB7,$AB$2:$AB$14,0))+('Weights of Rankings'!$D$3*rank(AD7,$AD$2:$AD$14,0))+('Weights of Rankings'!$D$5*rank(AF7,$AF$2:$AF$14,0))+('Weights of Rankings'!$D$7*rank(AH7,$AH$2:$AH$14,0))+('Weights of Rankings'!$D$8*rank(AJ7,$AJ$2:$AJ$14,0))+('Weights of Rankings'!$D$9*rank(AL7,$AL$2:$AL$14,0))+('Weights of Rankings'!$D$11*rank(AM7,$AM$2:$AM$14,0))+('Weights of Rankings'!$D$12*rank(AO7,$AO$2:$AO$14,0)) -> 39 | AR7: =('Weights of Rankings'!$D$1*rank(AC7,$AC$2:$AC$14,0))+('Weights of Rankings'!$D$3*rank(AE7,$AE$2:$AE$14,0))+('Weights of Rankings'!$D$5*rank(AG7,$AG$2:$AG$14,0))+('Weights of Rankings'!$D$7*rank(AI7,$AI$2:$AI$14,0))+('Weights of Rankings'!$D$8*rank(AK7,$AK$2:$AK$14,0))+('Weights of Rankings'!$D$9*rank(AM7,$AM$2:$AM$14,0))+('Weights of Rankings'!$D$11*rank(AN7,$AN$2:$AN$14,0))+('Weights of Rankings'!$D$12*rank(AP7,$AP$2:$AP$14,0)) -> 44 | AS7: =rank(AQ7,$AQ$2:$AQ$14,1) -> 5 | AT7: =rank(AR7,$AR$2:$AR$14,1) -> 6
A8: Zach | B8: 5 | C8: 0 | D8: 5 | E8: 0 | F8: 6 | G8: 0 | H8: 7 | I8: 4 | J8: 2 | K8: 0 | L8: 3 | M8: 0 | N8: 5 | O8: 0 | P8: 2 | Q8: 0 | R8: 2 | S8: 0 | T8: 3 | U8: 0 | V8: 6 | W8: 0 | X8: 9 | Y8: 4 | Z8: 8 | AA8: 4 | AB8: =AD8+AF8 -> 75 | AC8: =AE8+AG8 -> 5.7692308 | AD8: =SUM(B8,D8,F8,H8,J8,L8,N8,P8,R8,T8,V8,X8,Z8) -> 63 | AE8: =AD8/(COUNT($B8:$AA8)/2) -> 4.8461538 | AF8: =SUM(C8,E8,G8,I8,K8,M8,O8,Q8,S8,U8,W8,Y8,AA8) -> 12 | AG8: =AF8/(COUNT($B8:$AA8)/2) -> 0.92307692 | AH8: =AJ8+AM8 -> 0 | AI8: =AK8+AN8 -> 0 | AJ8: =COUNTIF(B8:AA8,10) -> 0 | AK8: =AJ8/(COUNT($B8:$AA8)/2) -> 0 | AL8: =COUNTIFS(B8:AA8,">6") -> 3 | AM8: =COUNTIFS(B8:AA8,"=5",$B$1:$AA$1,"*P*") -> 0 | AN8: =AM8/(COUNT($B8:$AA8)/2) -> 0 | AO8: =(((COUNT(B8:M8)/2)*-25)+((Count(N8:W8)/2)*-50)+((Count(X8:AA8)/2)*-100))+((COUNTIF(B8:M8,10))*100)+((COUNTIF(B8:M8,9))*50)+((COUNTIF(B8:M8,8))*25)+((COUNTIF(N8:W8,10))*200)+((COUNTIF(N8:W8,9))*100)+((COUNTIF(N8:W8,8))*50)+((COUNTIF(X8:AA8,10))*400)+((COUNTIF(X8:AA8,9))*200)+((COUNTIF(X8:AA8,8))*100)+((COUNTIFS(B8:M8,5,$B$1:$M$1,"*P*")*50))+((COUNTIFS(B8:M8,4,$B$1:$M$1,"*P*")*25))+((COUNTIFS(N8:W8,5,$N$1:$W$1,"*P*")*100))+((COUNTIFS(N8:W8,4,$N$1:$W$1,"*P*")*50))+((COUNTIFS(X8:AA8,5,$X$1:$AA$1,"*P*")*200))+((COUNTIFS(X8:AA8,4,$X$1:$AA$1,"*P*")*100)) -> -75 | AP8: =AO8/(COUNT($B8:$AA8)/2) -> -5.7692308 | AQ8: =('Weights of Rankings'!$D$1*rank(AB8,$AB$2:$AB$14,0))+('Weights of Rankings'!$D$3*rank(AD8,$AD$2:$AD$14,0))+('Weights of Rankings'!$D$5*rank(AF8,$AF$2:$AF$14,0))+('Weights of Rankings'!$D$7*rank(AH8,$AH$2:$AH$14,0))+('Weights of Rankings'!$D$8*rank(AJ8,$AJ$2:$AJ$14,0))+('Weights of Rankings'!$D$9*rank(AL8,$AL$2:$AL$14,0))+('Weights of Rankings'!$D$11*rank(AM8,$AM$2:$AM$14,0))+('Weights of Rankings'!$D$12*rank(AO8,$AO$2:$AO$14,0)) -> 66 | AR8: =('Weights of Rankings'!$D$1*rank(AC8,$AC$2:$AC$14,0))+('Weights of Rankings'!$D$3*rank(AE8,$AE$2:$AE$14,0))+('Weights of Rankings'!$D$5*rank(AG8,$AG$2:$AG$14,0))+('Weights of Rankings'!$D$7*rank(AI8,$AI$2:$AI$14,0))+('Weights of Rankings'!$D$8*rank(AK8,$AK$2:$AK$14,0))+('Weights of Rankings'!$D$9*rank(AM8,$AM$2:$AM$14,0))+('Weights of Rankings'!$D$11*rank(AN8,$AN$2:$AN$14,0))+('Weights of Rankings'!$D$12*rank(AP8,$AP$2:$AP$14,0)) -> 62 | AS8: =rank(AQ8,$AQ$2:$AQ$14,1) -> 8 | AT8: =rank(AR8,$AR$2:$AR$14,1) -> 8
A9: Johnny | B9: 7 | C9: 5 | D9: 6 | E9: 0 | F9: 2 | G9: 0 | H9: 2 | I9: 0 | J9: 7 | K9: 3 | L9: 10 | M9: 5 | N9: 8 | O9: 3 | P9: 8 | Q9: 4 | R9: 6 | S9: 0 | T9: 8 | U9: 5 | V9: 1 | W9: 0 | X9: 3 | Y9: 0 | Z9: 10 | AA9: 3 | AB9: =AD9+AF9 -> 106 | AC9: =AE9+AG9 -> 8.1538462 | AD9: =SUM(B9,D9,F9,H9,J9,L9,N9,P9,R9,T9,V9,X9,Z9) -> 78 | AE9: =AD9/(COUNT($B9:$AA9)/2) -> 6 | AF9: =SUM(C9,E9,G9,I9,K9,M9,O9,Q9,S9,U9,W9,Y9,AA9) -> 28 | AG9: =AF9/(COUNT($B9:$AA9)/2) -> 2.1538462 | AH9: =AJ9+AM9 -> 5 | AI9: =AK9+AN9 -> 0.38461538 | AJ9: =COUNTIF(B9:AA9,10) -> 2 | AK9: =AJ9/(COUNT($B9:$AA9)/2) -> 0.15384615 | AL9: =COUNTIFS(B9:AA9,">6") -> 7 | AM9: =COUNTIFS(B9:AA9,"=5",$B$1:$AA$1,"*P*") -> 3 | AN9: =AM9/(COUNT($B9:$AA9)/2) -> 0.23076923 | AO9: =(((COUNT(B9:M9)/2)*-25)+((Count(N9:W9)/2)*-50)+((Count(X9:AA9)/2)*-100))+((COUNTIF(B9:M9,10))*100)+((COUNTIF(B9:M9,9))*50)+((COUNTIF(B9:M9,8))*25)+((COUNTIF(N9:W9,10))*200)+((COUNTIF(N9:W9,9))*100)+((COUNTIF(N9:W9,8))*50)+((COUNTIF(X9:AA9,10))*400)+((COUNTIF(X9:AA9,9))*200)+((COUNTIF(X9:AA9,8))*100)+((COUNTIFS(B9:M9,5,$B$1:$M$1,"*P*")*50))+((COUNTIFS(B9:M9,4,$B$1:$M$1,"*P*")*25))+((COUNTIFS(N9:W9,5,$N$1:$W$1,"*P*")*100))+((COUNTIFS(N9:W9,4,$N$1:$W$1,"*P*")*50))+((COUNTIFS(X9:AA9,5,$X$1:$AA$1,"*P*")*200))+((COUNTIFS(X9:AA9,4,$X$1:$AA$1,"*P*")*100)) -> 300 | AP9: =AO9/(COUNT($B9:$AA9)/2) -> 23.076923 | AQ9: =('Weights of Rankings'!$D$1*rank(AB9,$AB$2:$AB$14,0))+('Weights of Rankings'!$D$3*rank(AD9,$AD$2:$AD$14,0))+('Weights of Rankings'!$D$5*rank(AF9,$AF$2:$AF$14,0))+('Weights of Rankings'!$D$7*rank(AH9,$AH$2:$AH$14,0))+('Weights of Rankings'!$D$8*rank(AJ9,$AJ$2:$AJ$14,0))+('Weights of Rankings'!$D$9*rank(AL9,$AL$2:$AL$14,0))+('Weights of Rankings'!$D$11*rank(AM9,$AM$2:$AM$14,0))+('Weights of Rankings'!$D$12*rank(AO9,$AO$2:$AO$14,0)) -> 21 | AR9: =('Weights of Rankings'!$D$1*rank(AC9,$AC$2:$AC$14,0))+('Weights of Rankings'!$D$3*rank(AE9,$AE$2:$AE$14,0))+('Weights of Rankings'!$D$5*rank(AG9,$AG$2:$AG$14,0))+('Weights of Rankings'!$D$7*rank(AI9,$AI$2:$AI$14,0))+('Weights of Rankings'!$D$8*rank(AK9,$AK$2:$AK$14,0))+('Weights of Rankings'!$D$9*rank(AM9,$AM$2:$AM$14,0))+('Weights of Rankings'!$D$11*rank(AN9,$AN$2:$AN$14,0))+('Weights of Rankings'!$D$12*rank(AP9,$AP$2:$AP$14,0)) -> 23 | AS9: =rank(AQ9,$AQ$2:$AQ$14,1) -> 3 | AT9: =rank(AR9,$AR$2:$AR$14,1) -> 3
A10: Eric | B10: 10 | C10: 4 | AB10: =AD10+AF10 -> 14 | AC10: =AE10+AG10 -> 14 | AD10: =SUM(B10,D10,F10,H10,J10,L10,N10,P10,R10,T10,V10,X10,Z10) -> 10 | AE10: =AD10/(COUNT($B10:$AA10)/2) -> 10 | AF10: =SUM(C10,E10,G10,I10,K10,M10,O10,Q10,S10,U10,W10,Y10,AA10) -> 4 | AG10: =AF10/(COUNT($B10:$AA10)/2) -> 4 | AH10: =AJ10+AM10 -> 1 | AI10: =AK10+AN10 -> 1 | AJ10: =COUNTIF(B10:AA10,10) -> 1 | AK10: =AJ10/(COUNT($B10:$AA10)/2) -> 1 | AL10: =COUNTIFS(B10:AA10,">6") -> 1 | AM10: =COUNTIFS(B10:AA10,"=5",$B$1:$AA$1,"*P*") -> 0 | AN10: =AM10/(COUNT($B10:$AA10)/2) -> 0 | AO10: =(((COUNT(B10:M10)/2)*-25)+((Count(N10:W10)/2)*-50)+((Count(X10:AA10)/2)*-100))+((COUNTIF(B10:M10,10))*100)+((COUNTIF(B10:M10,9))*50)+((COUNTIF(B10:M10,8))*25)+((COUNTIF(N10:W10,10))*200)+((COUNTIF(N10:W10,9))*100)+((COUNTIF(N10:W10,8))*50)+((COUNTIF(X10:AA10,10))*400)+((COUNTIF(X10:AA10,9))*200)+((COUNTIF(X10:AA10,8))*100)+((COUNTIFS(B10:M10,5,$B$1:$M$1,"*P*")*50))+((COUNTIFS(B10:M10,4,$B$1:$M$1,"*P*")*25))+((COUNTIFS(N10:W10,5,$N$1:$W$1,"*P*")*100))+((COUNTIFS(N10:W10,4,$N$1:$W$1,"*P*")*50))+((COUNTIFS(X10:AA10,5,$X$1:$AA$1,"*P*")*200))+((COUNTIFS(X10:AA10,4,$X$1:$AA$1,"*P*")*100)) -> 100 | AP10: =AO10/(COUNT($B10:$AA10)/2) -> 100 | AQ10: =('Weights of Rankings'!$D$1*rank(AB10,$AB$2:$AB$14,0))+('Weights of Rankings'!$D$3*rank(AD10,$AD$2:$AD$14,0))+('Weights of Rankings'!$D$5*rank(AF10,$AF$2:$AF$14,0))+('Weights of Rankings'!$D$7*rank(AH10,$AH$2:$AH$14,0))+('Weights of Rankings'!$D$8*rank(AJ10,$AJ$2:$AJ$14,0))+('Weights of Rankings'!$D$9*rank(AL10,$AL$2:$AL$14,0))+('Weights of Rankings'!$D$11*rank(AM10,$AM$2:$AM$14,0))+('Weights of Rankings'!$D$12*rank(AO10,$AO$2:$AO$14,0)) -> 58 | AR10: =('Weights of Rankings'!$D$1*rank(AC10,$AC$2:$AC$14,0))+('Weights of Rankings'!$D$3*rank(AE10,$AE$2:$AE$14,0))+('Weights of Rankings'!$D$5*rank(AG10,$AG$2:$AG$14,0))+('Weights of Rankings'!$D$7*rank(AI10,$AI$2:$AI$14,0))+('Weights of Rankings'!$D$8*rank(AK10,$AK$2:$AK$14,0))+('Weights of Rankings'!$D$9*rank(AM10,$AM$2:$AM$14,0))+('Weights of Rankings'!$D$11*rank(AN10,$AN$2:$AN$14,0))+('Weights of Rankings'!$D$12*rank(AP10,$AP$2:$AP$14,0)) -> 22 | AS10: =rank(AQ10,$AQ$2:$AQ$14,1) -> 7 | AT10: =rank(AR10,$AR$2:$AR$14,1) -> 2
A11: Kevin | D11: 2 | E11: 0 | AB11: =AD11+AF11 -> 2 | AC11: =AE11+AG11 -> 2 | AD11: =SUM(B11,D11,F11,H11,J11,L11,N11,P11,R11,T11,V11,X11,Z11) -> 2 | AE11: =AD11/(COUNT($B11:$AA11)/2) -> 2 | AF11: =SUM(C11,E11,G11,I11,K11,M11,O11,Q11,S11,U11,W11,Y11,AA11) -> 0 | AG11: =AF11/(COUNT($B11:$AA11)/2) -> 0 | AH11: =AJ11+AM11 -> 0 | AI11: =AK11+AN11 -> 0 | AJ11: =COUNTIF(B11:AA11,10) -> 0 | AK11: =AJ11/(COUNT($B11:$AA11)/2) -> 0 | AL11: =COUNTIFS(B11:AA11,">6") -> 0 | AM11: =COUNTIFS(B11:AA11,"=5",$B$1:$AA$1,"*P*") -> 0 | AN11: =AM11/(COUNT($B11:$AA11)/2) -> 0 | AO11: =(((COUNT(B11:M11)/2)*-25)+((Count(N11:W11)/2)*-50)+((Count(X11:AA11)/2)*-100))+((COUNTIF(B11:M11,10))*100)+((COUNTIF(B11:M11,9))*50)+((COUNTIF(B11:M11,8))*25)+((COUNTIF(N11:W11,10))*200)+((COUNTIF(N11:W11,9))*100)+((COUNTIF(N11:W11,8))*50)+((COUNTIF(X11:AA11,10))*400)+((COUNTIF(X11:AA11,9))*200)+((COUNTIF(X11:AA11,8))*100)+((COUNTIFS(B11:M11,5,$B$1:$M$1,"*P*")*50))+((COUNTIFS(B11:M11,4,$B$1:$M$1,"*P*")*25))+((COUNTIFS(N11:W11,5,$N$1:$W$1,"*P*")*100))+((COUNTIFS(N11:W11,4,$N$1:$W$1,"*P*")*50))+((COUNTIFS(X11:AA11,5,$X$1:$AA$1,"*P*")*200))+((COUNTIFS(X11:AA11,4,$X$1:$AA$1,"*P*")*100)) -> -25 | AP11: =AO11/(COUNT($B11:$AA11)/2) -> -25 | AQ11: =('Weights of Rankings'!$D$1*rank(AB11,$AB$2:$AB$14,0))+('Weights of Rankings'!$D$3*rank(AD11,$AD$2:$AD$14,0))+('Weights of Rankings'!$D$5*rank(AF11,$AF$2:$AF$14,0))+('Weights of Rankings'!$D$7*rank(AH11,$AH$2:$AH$14,0))+('Weights of Rankings'!$D$8*rank(AJ11,$AJ$2:$AJ$14,0))+('Weights of Rankings'!$D$9*rank(AL11,$AL$2:$AL$14,0))+('Weights of Rankings'!$D$11*rank(AM11,$AM$2:$AM$14,0))+('Weights of Rankings'!$D$12*rank(AO11,$AO$2:$AO$14,0)) -> 80 | AR11: =('Weights of Rankings'!$D$1*rank(AC11,$AC$2:$AC$14,0))+('Weights of Rankings'!$D$3*rank(AE11,$AE$2:$AE$14,0))+('Weights of Rankings'!$D$5*rank(AG11,$AG$2:$AG$14,0))+('Weights of Rankings'!$D$7*rank(AI11,$AI$2:$AI$14,0))+('Weights of Rankings'!$D$8*rank(AK11,$AK$2:$AK$14,0))+('Weights of Rankings'!$D$9*rank(AM11,$AM$2:$AM$14,0))+('Weights of Rankings'!$D$11*rank(AN11,$AN$2:$AN$14,0))+('Weights of Rankings'!$D$12*rank(AP11,$AP$2:$AP$14,0)) -> 90 | AS11: =rank(AQ11,$AQ$2:$AQ$14,1) -> 11 | AT11: =rank(AR11,$AR$2:$AR$14,1) -> 12
A12: Ryan | F12: 1 | G12: 0 | H12: 10 | I12: 5 | J12: 9 | K12: 3 | L12: 9 | M12: 4 | N12: 1 | O12: 0 | P12: 1 | Q12: 0 | R12: 9 | S12: 3 | T12: 4 | U12: 0 | V12: 3 | W12: 0 | X12: 2 | Y12: 0 | Z12: 2 | AA12: 0 | AB12: =AD12+AF12 -> 66 | AC12: =AE12+AG12 -> 6 | AD12: =SUM(B12,D12,F12,H12,J12,L12,N12,P12,R12,T12,V12,X12,Z12) -> 51 | AE12: =AD12/(COUNT($B12:$AA12)/2) -> 4.6363636 | AF12: =SUM(C12,E12,G12,I12,K12,M12,O12,Q12,S12,U12,W12,Y12,AA12) -> 15 | AG12: =AF12/(COUNT($B12:$AA12)/2) -> 1.3636364 | AH12: =AJ12+AM12 -> 2 | AI12: =AK12+AN12 -> 0.18181818 | AJ12: =COUNTIF(B12:AA12,10) -> 1 | AK12: =AJ12/(COUNT($B12:$AA12)/2) -> 0.090909091 | AL12: =COUNTIFS(B12:AA12,">6") -> 4 | AM12: =COUNTIFS(B12:AA12,"=5",$B$1:$AA$1,"*P*") -> 1 | AN12: =AM12/(COUNT($B12:$AA12)/2) -> 0.090909091 | AO12: =(((COUNT(B12:M12)/2)*-25)+((Count(N12:W12)/2)*-50)+((Count(X12:AA12)/2)*-100))+((COUNTIF(B12:M12,10))*100)+((COUNTIF(B12:M12,9))*50)+((COUNTIF(B12:M12,8))*25)+((COUNTIF(N12:W12,10))*200)+((COUNTIF(N12:W12,9))*100)+((COUNTIF(N12:W12,8))*50)+((COUNTIF(X12:AA12,10))*400)+((COUNTIF(X12:AA12,9))*200)+((COUNTIF(X12:AA12,8))*100)+((COUNTIFS(B12:M12,5,$B$1:$M$1,"*P*")*50))+((COUNTIFS(B12:M12,4,$B$1:$M$1,"*P*")*25))+((COUNTIFS(N12:W12,5,$N$1:$W$1,"*P*")*100))+((COUNTIFS(N12:W12,4,$N$1:$W$1,"*P*")*50))+((COUNTIFS(X12:AA12,5,$X$1:$AA$1,"*P*")*200))+((COUNTIFS(X12:AA12,4,$X$1:$AA$1,"*P*")*100)) -> -175 | AP12: =AO12/(COUNT($B12:$AA12)/2) -> -15.909091 | AQ12: =('Weights of Rankings'!$D$1*rank(AB12,$AB$2:$AB$14,0))+('Weights of Rankings'!$D$3*rank(AD12,$AD$2:$AD$14,0))+('Weights of Rankings'!$D$5*rank(AF12,$AF$2:$AF$14,0))+('Weights of Rankings'!$D$7*rank(AH12,$AH$2:$AH$14,0))+('Weights of Rankings'!$D$8*rank(AJ12,$AJ$2:$AJ$14,0))+('Weights of Rankings'!$D$9*rank(AL12,$AL$2:$AL$14,0))+('Weights of Rankings'!$D$11*rank(AM12,$AM$2:$AM$14,0))+('Weights of Rankings'!$D$12*rank(AO12,$AO$2:$AO$14,0)) -> 73 | AR12: =('Weights of Rankings'!$D$1*rank(AC12,$AC$2:$AC$14,0))+('Weights of Rankings'!$D$3*rank(AE12,$AE$2:$AE$14,0))+('Weights of Rankings'!$D$5*rank(AG12,$AG$2:$AG$14,0))+('Weights of Rankings'!$D$7*rank(AI12,$AI$2:$AI$14,0))+('Weights of Rankings'!$D$8*rank(AK12,$AK$2:$AK$14,0))+('Weights of Rankings'!$D$9*rank(AM12,$AM$2:$AM$14,0))+('Weights of Rankings'!$D$11*rank(AN12,$AN$2:$AN$14,0))+('Weights of Rankings'!$D$12*rank(AP12,$AP$2:$AP$14,0)) -> 64 | AS12: =rank(AQ12,$AQ$2:$AQ$14,1) -> 9 | AT12: =rank(AR12,$AR$2:$AR$14,1) -> 9
A13: Winston | B13: 4 | C13: 0 | D13: 8 | E13: 3 | F13: 3 | G13: 0 | H13: 6 | I13: 0 | J13: 6 | K13: 0 | L13: 1 | M13: 0 | AB13: =AD13+AF13 -> 31 | AC13: =AE13+AG13 -> 5.1666667 | AD13: =SUM(B13,D13,F13,H13,J13,L13,N13,P13,R13,T13,V13,X13,Z13) -> 28 | AE13: =AD13/(COUNT($B13:$AA13)/2) -> 4.6666667 | AF13: =SUM(C13,E13,G13,I13,K13,M13,O13,Q13,S13,U13,W13,Y13,AA13) -> 3 | AG13: =AF13/(COUNT($B13:$AA13)/2) -> 0.5 | AH13: =AJ13+AM13 -> 0 | AI13: =AK13+AN13 -> 0 | AJ13: =COUNTIF(B13:AA13,10) -> 0 | AK13: =AJ13/(COUNT($B13:$AA13)/2) -> 0 | AL13: =COUNTIFS(B13:AA13,">6") -> 1 | AM13: =COUNTIFS(B13:AA13,"=5",$B$1:$AA$1,"*P*") -> 0 | AN13: =AM13/(COUNT($B13:$AA13)/2) -> 0 | AO13: =(((COUNT(B13:M13)/2)*-25)+((Count(N13:W13)/2)*-50)+((Count(X13:AA13)/2)*-100))+((COUNTIF(B13:M13,10))*100)+((COUNTIF(B13:M13,9))*50)+((COUNTIF(B13:M13,8))*25)+((COUNTIF(N13:W13,10))*200)+((COUNTIF(N13:W13,9))*100)+((COUNTIF(N13:W13,8))*50)+((COUNTIF(X13:AA13,10))*400)+((COUNTIF(X13:AA13,9))*200)+((COUNTIF(X13:AA13,8))*100)+((COUNTIFS(B13:M13,5,$B$1:$M$1,"*P*")*50))+((COUNTIFS(B13:M13,4,$B$1:$M$1,"*P*")*25))+((COUNTIFS(N13:W13,5,$N$1:$W$1,"*P*")*100))+((COUNTIFS(N13:W13,4,$N$1:$W$1,"*P*")*50))+((COUNTIFS(X13:AA13,5,$X$1:$AA$1,"*P*")*200))+((COUNTIFS(X13:AA13,4,$X$1:$AA$1,"*P*")*100)) -> -125 | AP13: =AO13/(COUNT($B13:$AA13)/2) -> -20.833333 | AQ13: =('Weights of Rankings'!$D$1*rank(AB13,$AB$2:$AB$14,0))+('Weights of Rankings'!$D$3*rank(AD13,$AD$2:$AD$14,0))+('Weights of Rankings'!$D$5*rank(AF13,$AF$2:$AF$14,0))+('Weights of Rankings'!$D$7*rank(AH13,$AH$2:$AH$14,0))+('Weights of Rankings'!$D$8*rank(AJ13,$AJ$2:$AJ$14,0))+('Weights of Rankings'!$D$9*rank(AL13,$AL$2:$AL$14,0))+('Weights of Rankings'!$D$11*rank(AM13,$AM$2:$AM$14,0))+('Weights of Rankings'!$D$12*rank(AO13,$AO$2:$AO$14,0)) -> 81 | AR13: =('Weights of Rankings'!$D$1*rank(AC13,$AC$2:$AC$14,0))+('Weights of Rankings'!$D$3*rank(AE13,$AE$2:$AE$14,0))+('Weights of Rankings'!$D$5*rank(AG13,$AG$2:$AG$14,0))+('Weights of Rankings'!$D$7*rank(AI13,$AI$2:$AI$14,0))+('Weights of Rankings'!$D$8*rank(AK13,$AK$2:$AK$14,0))+('Weights of Rankings'!$D$9*rank(AM13,$AM$2:$AM$14,0))+('Weights of Rankings'!$D$11*rank(AN13,$AN$2:$AN$14,0))+('Weights of Rankings'!$D$12*rank(AP13,$AP$2:$AP$14,0)) -> 77 | AS13: =rank(AQ13,$AQ$2:$AQ$14,1) -> 12 | AT13: =rank(AR13,$AR$2:$AR$14,1) -> 11
A14: Max | N14: 2 | O14: 0 | P14: 6 | Q14: 0 | R14: 4 | S14: 0 | T14: 7 | U14: 3 | V14: 4 | W14: 0 | X14: 1 | Y14: 0 | Z14: 3 | AA14: 0 | AB14: =AD14+AF14 -> 30 | AC14: =AE14+AG14 -> 4.2857143 | AD14: =SUM(B14,D14,F14,H14,J14,L14,N14,P14,R14,T14,V14,X14,Z14) -> 27 | AE14: =AD14/(COUNT($B14:$AA14)/2) -> 3.8571429 | AF14: =SUM(C14,E14,G14,I14,K14,M14,O14,Q14,S14,U14,W14,Y14,AA14) -> 3 | AG14: =AF14/(COUNT($B14:$AA14)/2) -> 0.42857143 | AH14: =AJ14+AM14 -> 0 | AI14: =AK14+AN14 -> 0 | AJ14: =COUNTIF(B14:AA14,10) -> 0 | AK14: =AJ14/(COUNT($B14:$AA14)/2) -> 0 | AL14: =COUNTIFS(B14:AA14,">6") -> 1 | AM14: =COUNTIFS(B14:AA14,"=5",$B$1:$AA$1,"*P*") -> 0 | AN14: =AM14/(COUNT($B14:$AA14)/2) -> 0 | AO14: =(((COUNT(B14:M14)/2)*-25)+((Count(N14:W14)/2)*-50)+((Count(X14:AA14)/2)*-100))+((COUNTIF(B14:M14,10))*100)+((COUNTIF(B14:M14,9))*50)+((COUNTIF(B14:M14,8))*25)+((COUNTIF(N14:W14,10))*200)+((COUNTIF(N14:W14,9))*100)+((COUNTIF(N14:W14,8))*50)+((COUNTIF(X14:AA14,10))*400)+((COUNTIF(X14:AA14,9))*200)+((COUNTIF(X14:AA14,8))*100)+((COUNTIFS(B14:M14,5,$B$1:$M$1,"*P*")*50))+((COUNTIFS(B14:M14,4,$B$1:$M$1,"*P*")*25))+((COUNTIFS(N14:W14,5,$N$1:$W$1,"*P*")*100))+((COUNTIFS(N14:W14,4,$N$1:$W$1,"*P*")*50))+((COUNTIFS(X14:AA14,5,$X$1:$AA$1,"*P*")*200))+((COUNTIFS(X14:AA14,4,$X$1:$AA$1,"*P*")*100)) -> -450 | AP14: =AO14/(COUNT($B14:$AA14)/2) -> -64.285714 | AQ14: =('Weights of Rankings'!$D$1*rank(AB14,$AB$2:$AB$14,0))+('Weights of Rankings'!$D$3*rank(AD14,$AD$2:$AD$14,0))+('Weights of Rankings'!$D$5*rank(AF14,$AF$2:$AF$14,0))+('Weights of Rankings'!$D$7*rank(AH14,$AH$2:$AH$14,0))+('Weights of Rankings'!$D$8*rank(AJ14,$AJ$2:$AJ$14,0))+('Weights of Rankings'!$D$9*rank(AL14,$AL$2:$AL$14,0))+('Weights of Rankings'!$D$11*rank(AM14,$AM$2:$AM$14,0))+('Weights of Rankings'!$D$12*rank(AO14,$AO$2:$AO$14,0)) -> 94 | AR14: =('Weights of Rankings'!$D$1*rank(AC14,$AC$2:$AC$14,0))+('Weights of Rankings'!$D$3*rank(AE14,$AE$2:$AE$14,0))+('Weights of Rankings'!$D$5*rank(AG14,$AG$2:$AG$14,0))+('Weights of Rankings'!$D$7*rank(AI14,$AI$2:$AI$14,0))+('Weights of Rankings'!$D$8*rank(AK14,$AK$2:$AK$14,0))+('Weights of Rankings'!$D$9*rank(AM14,$AM$2:$AM$14,0))+('Weights of Rankings'!$D$11*rank(AN14,$AN$2:$AN$14,0))+('Weights of Rankings'!$D$12*rank(AP14,$AP$2:$AP$14,0)) -> 92 | AS14: =rank(AQ14,$AQ$2:$AQ$14,1) -> 13 | AT14: =rank(AR14,$AR$2:$AR$14,1) -> 13

Sheet League Trades
A1: Year | B1: Team 1 | C1: Team 1 Received | E1: Team 2 | F1: Team 2 Received | H1: Fun Trade Notes
A2: 2013-2014 | H2: Players Traded Multiple Times
A3: 2014-2015 | B3: Jordan | C3: Aaron Rodgers | E3: Matt | F3: Colin Kaepernick | H3: Player | I3: # of Times Traded
C4: 2014 2nd | F4: Lamar Miller | H4: AJ Brown | I4: 5
C5: 9 | F5: Tavon Austin | H5: Travis Kelce | I5: 4
C6: 2015 2nd (if Austin is cut) | F6: 2014 2nd | H6: Melvin Gordon | I6: 3
F7: $8 (if Austin is cut) | H7: Marquis Brown | I7: 3
B8: Jordan | C8: Matt Ryan | E8: Ben | F8: Marquis Lee | H8: David Montgomery | I8: 3
C9: 2015 2nd | F9: Bernard Pierce | H9: Matt Ryan | I9: 2
F10: 2015 1st | H10: Tom Brady | I10: 2
B11: Ben | C11: Tom Brady | E11: Qasim | F11: Brandin Cooks | H11: CJ Spiller | I11: 2
C12: Steve Smith | F12: Roddy White | H12: Doug Martin | I12: 2
F13: Wes Welker | H13: Doug Baldwin | I13: 2
F14: $4 (If Welker is cut) | H14: Randall Cobb | I14: 2
F15: $8 (If Welker retires or isnt on a roster for week 1) | H15: Colin Kaepernick | I15: 2
A16: 2015-2016 | B16: Jordan | C16: Joique Bell | E16: Ryan | F16: 2015 2nd | H16: Ezekiel Elliot | I16: 2
B17: Ryan | C17: 2015 1st | E17: Matt | F17: Jimmy Graham | H17: Joe Mixon | I17: 2
C18: Colin Kaepernick | F18: Jeremy Maclin | H18: DeAndre Hopkins | I18: 2
C19: CJ Spiller | H19: Russell Wilson | I19: 2
C20: 9 | H20: Julio Jones | I20: 2
B21: Ryan | C21: 2015 1st | E21: Zach | F21: CJ Spiller | H21: Aaron Rodgers | I21: 2
F22: 14 | H22: Michael Gallup | I22: 2
B23: Jordan | C23: Larry Fitzgerald | E23: Qasim | F23: Matt Ryan | H23: Davante Adams | I23: 2
C24: 2015 2nd | H24: Matt Stafford | I24: 2
C25: 3 | H25: Dallas Goedert | I25: 2
B26: Jordan | C26: Doug Martin | E26: Ryan | F26: 2016 1st | H26: Puka Nacua | I26: 2
C27: 28 | F27: 2016 2nd (from Qasim) (if Martin and Williams score 240 + points starting Nov. 7) | H27: Alec Pierce | I27: 2
F28: 2016 2nd (if Martin and William score 130-239 points starting Nov. 7) | H28: 1st Round Picks | I28: 41
B29: Johnny | C29: Tom Brady | E29: Ben | F29: Randall Cobb | H29: 2nd Round Picks | I29: 39
C30: CJ Anderson | F30: 2016 1st | H30: 3rd Round Picks | I30: 18
C31: Rishard Matthews | H31: Total $ | I31: 662
C32: 2016 2nd | H32: Biggest $ | I32: 65
A33: 2016-2017 | B33: Ryan | C33: Doug Baldwin | E33: Ben | F33: Corey Coleman
F34: 2018 1st
F35: 2018 3rd
F36: 20
B37: Jordan | C37: Randall Cobb | E37: Ben | F37: Antonio Brown
C38: 2017 1st | F38: Jordan Matthews
C39: 2018 1st | F39: 25
C40: 2018 2nd
...

Sheet 2014 Rookie Draft
B1: Team | C1: Selection
A2: 1st Round | D2: 2nd Round | G2: 3rd Round
A3: Pick 1 | B3: Matt | C3: Bishop Sankey | D3: Pick 1 | E3: Jordan | F3: Jordan Matthews | G3: Pick 1 | H3: Matt | I3: Allen Robinson
A4: Pick 2 | B4: Qasim | C4: Sammy Watkins | D4: Pick 2 | E4: Qasim | F4: Odell Beckham Jr | G4: Pick 2 | H4: Qasim | I4: Andre Williams
A5: Pick 3 | B5: Ben | C5: Brandin Cooks | D5: Pick 3 | E5: Ben | F5: Jeremy Hill | G5: Pick 3 | H5: Ben | I5: John Brown
A6: Pick 4 | B6: Winston | C6: Carlos Hyde | D6: Pick 4 | E6: Winston | F6: Eric Ebron | G6: Pick 4 | H6: Winston | I6: Martavis Bryant
A7: Pick 5 | B7: Zach | C7: Mike Evans | D7: Pick 5 | E7: Zach | F7: Jace Amaro | G7: Pick 5 | H7: Zach | I7: Alfred Blue
A8: Pick 6 | B8: Mike | C8: Kelvin Benjamin | D8: Pick 6 | E8: Mike | F8: Devonta Freeman | G8: Pick 6 | H8: Mike | I8: Derek Carr
A9: Pick 7 | B9: Johnny | C9: Johnny Manziel | D9: Pick 7 | E9: Johnny | F9: Teddy Bridgewater | G9: Pick 7 | H9: Johnny | I9: Cody Latimer
A10: Pick 8 | B10: Jordan | C10: Marqise Lee | D10: Pick 8 | E10: Matt | F10: Ka'Deem Carey | G10: Pick 8 | H10: Jordan | I10: Austin Seferian-Jenkins
A11: Pick 9 | B11: Russ | C11: Tre Mason | D11: Pick 9 | E11: Russ | F11: Blake Bortles | G11: Pick 9 | H11: Russ | I11: Devin Street
A12: Pick 10 | B12: Kevin | C12: Terrence West | D12: Pick 10 | E12: Kevin | F12: Davante Adams | G12: Pick 10 | H12: Kevin | I12: Jerrick McKinnon

Sheet Weights of Rankings
A1: Total Score | B1: 7 | C1: Total Score | D1: 0 | F1: Total Score | G1: 4
A2: Total Avg | B2: 10 | C2: Total Avg | D2: 0 | F2: Total Avg
A3: R Score | B3: 2 | C3: R Score | D3: 1 | F3: R Score | G3: 3
A4: R Avg | B4: 9 | C4: R Avg | D4: 0 | F4: R Avg
A5: P Score | B5: 1 | C5: P Score | D5: 1 | F5: P Score | G5: 2
A6: P Avg | B6: 8 | C6: P Avg | D6: 0 | F6: P Avg
A7: Total Titles | B7: 6 | C7: Total Titles | D7: 0 | F7: Total Titles | G7: 7
A8: R Titles | B8: 5 | C8: R Titles | D8: 0 | F8: R Titles | G8: 6
A9: Make Playoffs | B9: 4 | C9: Make Playoffs | D9: 2 | F9: Make Playoffs | G9: 1
A10: P Titles | B10: 3 | C10: Make Playoffs % | D10: 0 | F10: Make Playoffs %
C11: P Titles | D11: 0 | F11: P Titles | G11: 5
C12: Profit | D12: 4 | F12: Profit | G12: 8

Sheet 2015 Rookie Draft
B1: 1 | C1: 2 | D1: 3
A2: 1 | B2: Ryan - Todd Gurley | C2: Jordan - Breshad Perriman | D2: Matt - Devin Smith
A3: 2 | B3: Ryan - Melvin Gordon | C3: Ryan - Dorial Green Beckham | D3: Ryan - Maxx Williams
A4: 3 | B4: Qasim - Amari Cooper | C4: Qasim - Marcus Mariotta | D4: Qasim - Javorius Allen
A5: 4 | B5: Mike - TJ Yeldon | C5: Mike - Phillip Dorsett | D5: Mike - Tyler Lockett
A6: 5 | B6: Ryan - Kevin White | C6: Zach - Duke Johnson | D6: Zach - Chris Conley
A7: 6 | B7: Johnny - Devante Parker | C7: Johnny - Jay Ajayi | D7: Johnny - Matt Jones
A8: 7 | B8: Ben - Tevin Coleman | C8: Ryan - Jaelen Strong | D8: Ben - Sammie Coates
A9: 8 | B9: Winston - Ameer Abdullah | C9: Winston - David Cobb | D9: Winston - Josh Robinson
A10: 9 | B10: Russell - Jameis Winston | C10: Russell - David Johnson | D10: Russell - Mike Davis
A11: 10 | B11: Ben - Nelson Agholor | C11: Jordan - Devin Funchess | D11: Jordan - Jeremy Langford

Sheet 2016 Rookie Draft
A1: Round:Pick | B1: Team - Player | C1: Round:Pick | D1: Team | E1: Round:Pick | F1: Team
A2: 1:1 | B2: Ryan - Ezekiel Elliot | C2: 2:1 | D2: Ben - Tyler Boyd | E2: 3:1 | F2: Ryan - Malcolm Mitchell
A3: 1:2 | B3: Ryan - Laquon Treadwell | C3: 2:2 | D3: Johnny - Jordan Howard | E3: 3:2 | F3: Johnny - Jared Goff
A4: 1:3 | B4: Winston - Josh Doctson | C4: 2:3 | D4: Winston - Kenyan Drake | E4: 3:3 | F4: Winston - Tyler Ervin
A5: 1:4 | B5: Matt - Derrick Henry | C5: 2:4 | D5: Matt - Will Fuller | E5: 3:4 | F5: Matt - Alex Collins
A6: 1:5 | B6: Ryan - Corey Coleman | C6: 2:5 | D6: Johnny - Tajae Sharpe | E6: 3:5 | F6: Ben - Wendall Smallwood
A7: 1:6 | B7: Zach - Sterling Shepard | C7: 2:6 | D7: Zach - Leonte Carroo | E7: 3:6 | F7: Zach - Hunter Henry
A8: 1:7 | B8: Russell - CJ Prosise | C8: 2:7 | D8: Russell - Braxton Miller | E8: 3:7 | F8: Russell - Trevor Davis
A9: 1:8 | B9: Ryan - Michael Thomas | C9: 2:8 | D9: Ryan - Pharoh Cooper | E9: 3:8 | F9: Jordan - Jonathan Williams
A10: 1:9 | B10: Qasim - Kenneth Dixon | C10: 2:9 | D10: Jordan - Paul Perkins | E10: 3:9 | F10: Qasim - Carson Wentz
A11: 0.048611111 | B11: Mike - DeVontae Booker | C11: 0.090277778 | D11: Mike - DeAndre Washington | E11: 0.13194444 | F11: Jordan - Paxton Lynch

Sheet 2017 Rookie Draft
B1: Round 1 | C1: Round 2 | D1: Round 3
A2: 1 | B2: Jordan - Leonard Fournette | C2: Jordan - John Ross | D2: Ben - Jamaal Williams
A3: 2 | B3: Johnny - Christian McCaffery | C3: Johnny - Evan Engram | D3: Johnny - Marlon Mack
A4: 3 | B4: Jordan - Joe Mixon | C4: Jordan - David Njoku | D4: Ben - Wayne Gallman
A5: 4 | B5: Qasim - Dalvin Cook | C5: Qasim - Zay Jones | D5: Ben - Kenny Golladay
A6: 5 | B6: Mike - Corey Davis | C6: Mike - D'onta Foreman | D6: Mike - DeShone Kizer
A7: 6 | B7: Winston - Samaje Perine | C7: Winston - Joe Williams | D7: Winston - Curtis Samuel
A8: 7 | B8: Zach - Kareem Hunt | C8: Zach - Cooper Kupp | D8: Zach - Deshaun Watson
A9: 8 | B9: Matt - Mike Williams | C9: Matt - Juju Smith-Schuster | D9: Matt - James Conner
A10: 9 | B10: Russell - Alvin Kamara | C10: Russell - Tarik Cohen | D10: Russell - Mack Hollins
A11: 10 | B11: Ryan - OJ Howard | C11: Jordan - Chris Godwin | D11: Ryan - Taywan Taylor

Sheet 2018 Rookie Draft
A1: Round | B1: 1 | C1: 2 | D1: 3
A2: Pick
A3: 1 | B3: Matt - Saquan Barkley | C3: Matt - Christian Kirk | D3: Matt - Lamar Jackson
A4: 2 | B4: Zach - Rashad Penny | C4: Zach - Courtland Sutton | D4: Zach - DJ Chark
A5: 3 | B5: Ryan - Ronald Jones II | C5: Ben - Michael Gallup | D5: Jordan - Tre’Quan Smith
A6: 4 | B6: Mike - Derrius Guice | C6: Jordan - Nyheim Hines | D6: Mike - Keke Coutee
A7: 5 | B7: Russ - DJ Moore | C7: Russ - Baker Mayfield | D7: Russ - Jordan Wilkins
A8: 6 | B8: Winston - Royce Freeman | C8: Winston - Mike Gesicki | D8: Winston - Josh Rosen
A9: 7 | B9: Johnny - Sony Michel | C9: Johnny - James Washington | D9: Johnny - J’Mon Moore
A10: 8 | B10: Mike - Calvin Ridley | C10: Mike - Sam Darnold | D10: Ben - Dallas Goedert
A11: 9 | B11: Ben - Kerryon Johnson | C11: Ryan - Anthony Miller | D11: Ben - Chase Edmonds
A12: 10 | B12: Qasim - Nick Chubb | C12: Qasim - Dante Pettis | D12: Qasim - Kelan Ballage

Sheet 2019 Rookie Draft
B1: Round | D1: Round | F1: Round
B2: 1 | D2: 2 | F2: 3
B3: Pick | C3: Team | D3: Pick | E3: Team | F3: Pick | G3: Team
B4: 1 - Josh Jacobs | C4: Max | D4: 1 - JJ Arcega-Whiteside | E4: Max | F4: 1 - Devin Singletary | G4: Max
B5: 2 - N'Keal Harry | C5: Ben | D5: 2 - Marquis Brown | E5: Ben | F5: 2 - Ryquell Armstead | G5: Jordan
B6: 3 - David Montgomery | C6: Zach | D6: 3 - TJ Hockenson | E6: Zach | F6: 3 - Benny Snell | G6: Zach
B7: 4 - Miles Sanders | C7: Mike | D7: 4 - Deebo Samuel | E7: Mike | F7: 4 - Alexander Mattison | G7: Mike
B8: 5 - AJ Brown | C8: Matt | D8: 5 - Noah Fant | E8: Matt | F8: 5 - Terry McLaurin | G8: Ryan
B9: 6 - DK Metcalf | C9: Qasim | D9: 6 - Hakeem Butler | E9: Qasim | F9: 6 - Dwayne Haskins | G9: Qasim
B10: 7 - Mecole Hardman | C10: Russ | D10: 7 - Andy Isabella | E10: Russ | F10: 7 - Tony Pollard | G10: Russ
B11: 8 - Darrell Henderson | C11: Jordan | D11: 8 - Damien Harris | E11: Ben | F11: 8 - Diontae Johnson | G11: Jordan
B12: 9 - Parris Campbell | C12: Ryan | D12: 9 - Justice Hill | E12: Ben | F12: 9 - Jalen Hurd | G12: Ryan
B13: 10 - Kyler Murray | C13: Johnny | D13: 10 - Irv Smith Jr | E13: Johnny | F13: 10 - Jace Sternburger | G13: Johnny
B15: Future picks 2020: jordan to Ryan 1st and 2nd | D15: Future picks 2021: jordan to Ryan 1st
B16: Ryan to jordan 3rd | D16: Ryan to jordan 3rd
B17: Ben to Ryan 1st | D17: Ben to Ryan 1st

Sheet 2020 Rookie Draft
B2: Round | D2: Round | F2: Round
B3: 1 | D3: 2 | F3: 3
B4: Pick | C4: Team | D4: Pick | E4: Team | F4: Pick | G4: Team
B5: 1 | C5: Ryan - Clyde Edwards-Helaire | D5: 1 | E5: Ryan - Jalen Reagor | F5: 1 | G5: Ben - Antonio Gibson
B6: 2 | C6: Max - Jonathan Taylor | D6: 2 | E6: Max - Brandon Aiyuk | F6: 2 | G6: Max - Tua Tagovailoa
B7: 3 | C7: Mike - D'Andre Swift | D7: 3 | E7: Mike - Michael Pittman Jr | F7: 3 | G7: Mike - Darrynton Evans
B8: 4 | C8: Qasim - JK Dobbins | D8: 4 | E8: Matt - Tee Higgins | F8: 4 | G8: Qasim - Adam Trautman
B9: 5 | C9: Zach - Cam Akers | D9: 5 | E9: Zach - Denzel Mims | F9: 5 | G9: Zach - Lynn Bowden Jr
B10: 6 | C10: Russ - Ceedee Lamb | D10: 6 | E10: Russ - Chase Claypool | F10: 6 | G10: Russ - Bryan Edwards
B11: 7 | C11: Ryan - Jerry Juedy | D11: 7 | E11: Ben - Zack Moss | F11: 7 | G11: Jordan - KJ Hamler
B12: 8 | C12: Johnny - Justin Jefferson | D12: 8 | E12: Johnny - Joe Burrow | F12: 8 | G12: Johnny - Cole Kmet
B13: 9 | C13: Ryan - Henry Ruggs III | D13: 9 | E13: Matt - Leviska Shenault Jr | F13: 9 | G13: Matt - Anthony McFarland Jr.
B14: 10 | C14: Matt - Ke'Shawn Vaughn | D14: 10 | E14: Ryan - AJ Dillon | F14: 10 | G14: Jordan - Antonio Gandy-Golden
B16: Future picks 2021: jordan to Ryan 1st | E16: Future Picks 2022: Ben to Jordan 2nd
B17: Ryan to jordan 3rd | E17: Qasim to Jordan 3rd
B18: Ben to Ryan 1st | E18: Matt gets Bens 3rd if its better and he didnt get it in 2021
B19: Matt to Ryan 1st
B20: Ben to Zach (via Jordan) 2nd
B21: Zach to Jordan 1st
B22: Qasim to Jordan 2nd
B23: Jordan ("highest # 3rd rounder) to Qasim
B24: Matt gets Bens 3rd if its better

Sheet 2021 Rookie Draft
B2: Round | D2: Round | F2: Round
B3: 1 | D3: 2 | F3: 3
B4: Pick | C4: Team | D4: Pick | E4: Team | F4: Pick | G4: Team
B5: 1 | C5: Ryan - Najee Harris | D5: 1 | E5: Ryan - Elijah Moore | F5: 1 | G5: Jordan - Nico Collins
B6: 2 | C6: Max - Ja'marr Chase | D6: 2 | E6: Zach - Michael Carter | F6: 2 | G6: Zach - Kenneth Gainwell
B7: 3 | C7: Ryan - Kyle PItts | D7: 3 | E7: Ben - Trevor Lawrence | F7: 3 | G7: Qasim - Zach Wilson
B8: 4 | C8: Russell - Travis Etienne | D8: 4 | E8: Russell - Justin Fields | F8: 4 | G8: Russell - Cornell Powell
B9: 5 | C9: Ryan - Javonte Williams | D9: 5 | E9: Zach - Terrace Marshall Jr | F9: 5 | G9: Matt - Pat Freiermuth
B10: 6 | C10: Max - Devonte Smith | D10: 6 | E10: Johnny - Trey Lance | F10: 6 | G10: Ben - Amari Rodgers
B11: 7 | C11: Ryan - Jaylen Waddle | D11: 7 | E11: Matt - Kadarius Toney | F11: 7 | G11: Max - Chuba Hubbard
B12: 8 | C12: Jordan - Rashod Bateman | D12: 8 | E12: Johnny - D'Wayne Eskridge | F12: 8 | G12: Johnny - Tutu Atwell
B13: 9 | C13: Mike - Trey Sermon | D13: 9 | E13: Mike - Amon-Ra St Brown | F13: 9 | G13: Mike - Josh Palmer
B14: 10 | C14: Ben - Rondale Moore | D14: 10 | E14: Johnny - Dyami Brown | F14: 10 | G14: Ben - Mac Jones
B15: Future Picks 2022: Ben to Jordan 2nd | G15: Future Picks 2023:
B16: Qasim to Jordan 3rd | G16: Qasim to Ryan 3rd | J16: Franchise tag #s
B17: Matt gets Bens 3rd if its better and he didnt get it in 2021 | J17: QB | K17: 38
B18: 1st from Max to Ben | J18: RB | K18: 63
B19: Ryan to Qasim 2nd | J19: WR | K19: 74
B20: Jordan to Matt 1st | J20: TE | K20: 41
J21: K | K21: 2
J22: D | K22: 2

Sheet 2022 Rookie Draft
B2: Round | D2: Round | F2: Round
B3: 1 | D3: 2 | F3: 3 | J3: Franchise tag #s
B4: Pick | C4: Team | D4: Pick | E4: Team | F4: Pick | G4: Team | J4: QB | K4: =(48+38+37+35+21)/5 -> 35.8
B5: 1 | C5: Ben - Breece Hall | D5: 1 | E5: Jordan - Skyy Moore | F5: 1 | G5: Ben - Alec Pierce | J5: RB | K5: =(99+82+66+63+63)/5 -> 74.6
B6: 2 | C6: Zach - Drake London | D6: 2 | E6: Zach - Rachaad White | F6: 2 | G6: Zach - Wan'Dale Robinson | J6: WR | K6: =(121+112+64+53+52)/5 -> 80.4
B7: 3 | C7: Zach - Treylon Burks | D7: 3 | E7: Jordan - Dameon Pierce | F7: 3 | G7: Jordan - Tyrion Davis-Price | J7: TE | K7: =(41+37+19+17+13)/5 -> 25.4
B8: 4 | C8: Ben - Kenneth Walker | D8: 4 | E8: Max - Isaiah Spiller | F8: 4 | G8: Max - Trey McBride | J8: K | K8: =((2+1+1+1+1)/5)+1 -> 2.2
B9: 5 | C9: Qasim - Garrett Wilson | D9: 5 | E9: Mike - Tyler Allgeier | F9: 5 | G9: Jordan - Romeo Doubs | J9: D | K9: =(4+3+2+1+1)/5 -> 2.2
B10: 6 | C10: Johnny - Chris Olave | D10: 6 | E10: Johnny - George Pickens | F10: 6 | G10: Johnny - Jelani Woods
B11: 7 | C11: Matt - Jameson Williams | D11: 7 | E11: Matt - David Bell | F11: 7 | G11: Matt - Malik Willis
B12: 8 | C12: Russ - James Cook | D12: 8 | E12: Russ - Zamir White | F12: 8 | G12: Russ - Snoop Conner
B13: 9 | C13: Ryan - Christian Watson | D13: 9 | E13: Qasim - Jalen Tolbert | F13: 9 | G13: Ryan - Tyquan Thornton
B14: 10 | C14: Mike - Jahan Dotson | D14: 10 | E14: Mike - Brian Robinson Jr. | F14: 10 | G14: Mike - Velus Jones Jr.
B15: Future Picks 2022: Ben to Jordan 2nd | E15: Future Picks 2023: | G15: Future Picks 2024: | I15: Future Picks 2025:
B16: Qasim to Jordan 3rd | E16: Qasim to Ryan 3rd
B17: Matt gets Bens 3rd if its better and he didnt get it in 2021 | E17: Matt to Zach 1st
B18: 1st from Max to Ben | E18: Zach to Matt 2nd
B19: Ryan to Qasim 2nd | E19: Mike to Jordan 2nd
B20: Jordan to Matt 1st
B21: Matt to Zach best of 1sts
B22: Qasim to Mike 2nd

Sheet 2023 Rookie Draft
B2: Round | D2: Round | F2: Round
B3: 1 | D3: 2 | F3: 3 | J3: Franchise tag #s
B4: Pick | C4: Team | D4: Pick | E4: Team | F4: Pick | G4: Team | J4: QB | K4: 27
B5: 1 | C5: Russ - Bijan Robinson | D5: 1 | E5: Russ - Israel Abinkanda | F5: 1 | G5: Russ - Josh Downs | J5: RB | K5: 94
B6: 2 | C6: Jordan - Jahmyr Gibbs | D6: 2 | E6: Ben - Kendre Miller | F6: 2 | G6: Jordan - Tank Bigsby | J6: WR | K6: 70
B7: 3 | C7: Zach - Jaxon Smith Njigba | D7: 3 | E7: Matt - Michael Mayer | F7: 3 | G7: Zach - CJ Stroud | J7: TE | K7: 30
B8: 4 | C8: Ryan - Jordan Addison | D8: 4 | E8: Ryan - Anthony Richardson | F8: 4 | G8: Ryan - Marvin Mims Jr | J8: K | K8: 2
B9: 5 | C9: Zach - Quentin Johnston | D9: 5 | E9: Matt - Rashee Rice | F9: 5 | G9: Russ - Chase Brown | J9: D | K9: 2
B10: 6 | C10: Jordan - Zach Charbonnet | D10: 6 | E10: Qasim - Tyjae Spears | F10: 6 | G10: Ryan - Jayden Reed
